2023-03-31 11:08:15,061 ERROR list index out of range
Traceback (most recent call last):
  File "C:\_PyPr\MCF_ARAM_dev\mcf_dev.py", line 37, in wrapper
    result = func(*args, **kwargs)
  File "C:\_PyPr\MCF_ARAM_dev\mcf_dev.py", line 364, in parsePoroGames
    result = PoroAPI.get_poro_games(red_champion=converted_champion, gamemode=event)
  File "C:\_PyPr\MCF_ARAM_dev\mcf_api.py", line 156, in get_poro_games
    ids = [int(str(ids.get('class')).split('-')[1]) for ids in game[0:5]]
  File "C:\_PyPr\MCF_ARAM_dev\mcf_api.py", line 156, in <listcomp>
    ids = [int(str(ids.get('class')).split('-')[1]) for ids in game[0:5]]
IndexError: list index out of range
2023-03-31 11:09:23,344 ERROR list index out of range
Traceback (most recent call last):
  File "C:\_PyPr\MCF_ARAM_dev\mcf_dev.py", line 37, in wrapper
    result = func(*args, **kwargs)
  File "C:\_PyPr\MCF_ARAM_dev\mcf_dev.py", line 364, in parsePoroGames
    result = PoroAPI.get_poro_games(red_champion=converted_champion, gamemode=event)
  File "C:\_PyPr\MCF_ARAM_dev\mcf_api.py", line 156, in get_poro_games
    ids = [int(str(ids.get('class')).split('-')[1]) for ids in game[0:5]]
  File "C:\_PyPr\MCF_ARAM_dev\mcf_api.py", line 156, in <listcomp>
    ids = [int(str(ids.get('class')).split('-')[1]) for ids in game[0:5]]
IndexError: list index out of range
2023-03-31 11:09:30,681 ERROR list index out of range
Traceback (most recent call last):
  File "C:\_PyPr\MCF_ARAM_dev\mcf_dev.py", line 37, in wrapper
    result = func(*args, **kwargs)
  File "C:\_PyPr\MCF_ARAM_dev\mcf_dev.py", line 364, in parsePoroGames
    result = PoroAPI.get_poro_games(red_champion=converted_champion, gamemode=event)
  File "C:\_PyPr\MCF_ARAM_dev\mcf_api.py", line 156, in get_poro_games
    ids = [int(str(ids.get('class')).split('-')[1]) for ids in game[0:5]]
  File "C:\_PyPr\MCF_ARAM_dev\mcf_api.py", line 156, in <listcomp>
    ids = [int(str(ids.get('class')).split('-')[1]) for ids in game[0:5]]
IndexError: list index out of range
2023-05-27 05:17:58,836 ERROR No module named 'mcf_build_dev'
Traceback (most recent call last):
  File "C:\_PyPr\MCF_ARAM\mcf_main.py", line 37, in wrapper
    result = func(*args, **kwargs)
             ^^^^^^^^^^^^^^^^^^^^^
  File "C:\_PyPr\MCF_ARAM\mcf_main.py", line 371, in parseAramGames
    from modules.GamesOnline import parsing_aram_api
  File "C:\_PyPr\MCF_ARAM\modules\GamesOnline.py", line 9, in <module>
    from mcf_build_dev import REGIONS_TUPLE, ELO_SYMBOLS
ModuleNotFoundError: No module named 'mcf_build_dev'
2023-05-27 05:21:05,096 ERROR name 'sw_afters' is not defined
Traceback (most recent call last):
  File "C:\_PyPr\MCF_ARAM\mcf_main.py", line 37, in wrapper
    result = func(*args, **kwargs)
             ^^^^^^^^^^^^^^^^^^^^^
  File "C:\_PyPr\MCF_ARAM\mcf_main.py", line 578, in runMainParser
    showMainInfo(text='Searching..')
  File "C:\_PyPr\MCF_ARAM\mcf_main.py", line 194, in showMainInfo
    if sw_afters['info'][0] is not None:
       ^^^^^^^^^
NameError: name 'sw_afters' is not defined
2023-06-20 11:48:50,581 ERROR Short

2023-06-20 11:48:54,605 ERROR Short

2023-06-20 11:48:58,473 ERROR list index out of range

2023-06-20 11:49:06,740 ERROR list index out of range

2023-06-20 11:49:18,724 ERROR list index out of range
Traceback (most recent call last):
  File "C:\_PyPr\New_MCF\mcf_riot_api.py", line 43, in wrapper
    result = func(*args, **kwargs)
             ^^^^^^^^^^^^^^^^^^^^^
  File "C:\_PyPr\New_MCF\mcf_riot_api.py", line 155, in get_poro_games
    ids = [int(str(ids.get('class')).split('-')[1]) for ids in game[0:5]]
          ^^^^^^^^^^^^^^^^^^^^^^^^^^^^^^^^^^^^^^^^^^^^^^^^^^^^^^^^^^^^^^^
  File "C:\_PyPr\New_MCF\mcf_riot_api.py", line 155, in <listcomp>
    ids = [int(str(ids.get('class')).split('-')[1]) for ids in game[0:5]]
               ~~~~~~~~~~~~~~~~~~~~~~~~~~~~~~~~^^^
IndexError: list index out of range
2023-06-20 11:49:57,669 ERROR list index out of range
Traceback (most recent call last):
  File "C:\_PyPr\New_MCF\mcf_riot_api.py", line 43, in wrapper
    result = func(*args, **kwargs)
             ^^^^^^^^^^^^^^^^^^^^^
  File "C:\_PyPr\New_MCF\mcf_riot_api.py", line 155, in get_poro_games
    ids = [int(str(ids.get('class')).split('-')[1]) for ids in game[0:5]]
          ^^^^^^^^^^^^^^^^^^^^^^^^^^^^^^^^^^^^^^^^^^^^^^^^^^^^^^^^^^^^^^^
  File "C:\_PyPr\New_MCF\mcf_riot_api.py", line 155, in <listcomp>
    ids = [int(str(ids.get('class')).split('-')[1]) for ids in game[0:5]]
               ~~~~~~~~~~~~~~~~~~~~~~~~~~~~~~~~^^^
IndexError: list index out of range
2023-06-20 11:51:11,591 ERROR Short
Traceback (most recent call last):
  File "C:\_PyPr\New_MCF\mcf_riot_api.py", line 43, in wrapper
    result = func(*args, **kwargs)
             ^^^^^^^^^^^^^^^^^^^^^
  File "C:\_PyPr\New_MCF\mcf_riot_api.py", line 111, in get_poro_games
    raise MCFException('Short')
mcf_build.MCFException: Short
2023-06-20 11:59:38,714 ERROR name 'ids' is not defined
Traceback (most recent call last):
  File "C:\_PyPr\New_MCF\mcf_riot_api.py", line 44, in wrapper
    result = func(*args, **kwargs)
             ^^^^^^^^^^^^^^^^^^^^^
  File "C:\_PyPr\New_MCF\mcf_riot_api.py", line 158, in get_poro_games
    converted_ids = [ALL_CHAMPIONS_IDs.get(i) for i in ids]
                                                       ^^^
NameError: name 'ids' is not defined
2023-06-20 12:01:20,191 ERROR 'str' object has no attribute 'startwidth'
Traceback (most recent call last):
  File "C:\_PyPr\New_MCF\mcf_riot_api.py", line 44, in wrapper
    result = func(*args, **kwargs)
             ^^^^^^^^^^^^^^^^^^^^^
  File "C:\_PyPr\New_MCF\mcf_riot_api.py", line 155, in get_poro_games
    if not game.get('class')[0].startwidth('champion'):
           ^^^^^^^^^^^^^^^^^^^^^^^^^^^^^^^
AttributeError: 'str' object has no attribute 'startwidth'
2023-06-20 12:01:32,731 ERROR 'str' object has no attribute 'startwith'
Traceback (most recent call last):
  File "C:\_PyPr\New_MCF\mcf_riot_api.py", line 44, in wrapper
    result = func(*args, **kwargs)
             ^^^^^^^^^^^^^^^^^^^^^
  File "C:\_PyPr\New_MCF\mcf_riot_api.py", line 155, in get_poro_games
    if not game.get('class')[0].startwith('champion'):
           ^^^^^^^^^^^^^^^^^^^^^^^^^^^^^^
AttributeError: 'str' object has no attribute 'startwith'
2023-06-20 12:02:54,180 ERROR ResultSet object has no attribute 'get'. You're probably treating a list of elements like a single element. Did you call find_all() when you meant to call find()?
Traceback (most recent call last):
  File "C:\_PyPr\New_MCF\mcf_riot_api.py", line 44, in wrapper
    result = func(*args, **kwargs)
             ^^^^^^^^^^^^^^^^^^^^^
  File "C:\_PyPr\New_MCF\mcf_riot_api.py", line 156, in get_poro_games
    if not game.get('class')[0].startswith('champion'):
           ^^^^^^^^
  File "C:\_PyPr\New_MCF\.env\Lib\site-packages\bs4\element.py", line 2289, in __getattr__
    raise AttributeError(
AttributeError: ResultSet object has no attribute 'get'. You're probably treating a list of elements like a single element. Did you call find_all() when you meant to call find()?
2023-06-20 12:04:36,522 ERROR list index out of range
Traceback (most recent call last):
  File "C:\_PyPr\New_MCF\mcf_riot_api.py", line 44, in wrapper
    result = func(*args, **kwargs)
             ^^^^^^^^^^^^^^^^^^^^^
  File "C:\_PyPr\New_MCF\mcf_riot_api.py", line 157, in get_poro_games
    if not champ.get('class')[0].startswith('champion'):
           ~~~~~~~~~~~~~~~~~~^^^
IndexError: list index out of range
2023-06-20 12:04:48,229 ERROR list index out of range
Traceback (most recent call last):
  File "C:\_PyPr\New_MCF\mcf_riot_api.py", line 44, in wrapper
    result = func(*args, **kwargs)
             ^^^^^^^^^^^^^^^^^^^^^
  File "C:\_PyPr\New_MCF\mcf_riot_api.py", line 157, in get_poro_games
    if not champ.get('class')[0].startswith('champion'):
           ~~~~~~~~~~~~~~~~~~^^^
IndexError: list index out of range
2023-06-20 12:05:36,275 ERROR 'list' object has no attribute 'startswith'
Traceback (most recent call last):
  File "C:\_PyPr\New_MCF\mcf_riot_api.py", line 44, in wrapper
    result = func(*args, **kwargs)
             ^^^^^^^^^^^^^^^^^^^^^
  File "C:\_PyPr\New_MCF\mcf_riot_api.py", line 157, in get_poro_games
    if not champ.get('class').startswith('champion'):
           ^^^^^^^^^^^^^^^^^^^^^^^^^^^^^
AttributeError: 'list' object has no attribute 'startswith'
2023-06-20 12:05:46,286 ERROR list index out of range
Traceback (most recent call last):
  File "C:\_PyPr\New_MCF\mcf_riot_api.py", line 44, in wrapper
    result = func(*args, **kwargs)
             ^^^^^^^^^^^^^^^^^^^^^
  File "C:\_PyPr\New_MCF\mcf_riot_api.py", line 157, in get_poro_games
    if not champ.get('class')[0].startswith('champion'):
           ~~~~~~~~~~~~~~~~~~^^^
IndexError: list index out of range
2023-06-20 12:08:51,949 ERROR Short
Traceback (most recent call last):
  File "C:\_PyPr\New_MCF\mcf_riot_api.py", line 44, in wrapper
    result = func(*args, **kwargs)
             ^^^^^^^^^^^^^^^^^^^^^
  File "C:\_PyPr\New_MCF\mcf_riot_api.py", line 112, in get_poro_games
    raise MCFException('Short')
mcf_build.MCFException: Short
2023-11-06 10:25:56,714 ERROR Task exception was never retrieved
future: <Task finished name='Task-7' coro=<parse_games.<locals>.parsing() done, defined at C:\python_field\modules\scripts\async_featured_games.py:23> exception=KeyError('gameList')>
Traceback (most recent call last):
  File "C:\python_field\modules\scripts\async_featured_games.py", line 31, in parsing
    gameList = data['gameList']
               ~~~~^^^^^^^^^^^^
KeyError: 'gameList'
2023-11-06 10:25:56,716 ERROR Task exception was never retrieved
future: <Task finished name='Task-8' coro=<parse_games.<locals>.parsing() done, defined at C:\python_field\modules\scripts\async_featured_games.py:23> exception=KeyError('gameList')>
Traceback (most recent call last):
  File "C:\python_field\modules\scripts\async_featured_games.py", line 31, in parsing
    gameList = data['gameList']
               ~~~~^^^^^^^^^^^^
KeyError: 'gameList'
2023-11-06 10:25:56,718 ERROR Task exception was never retrieved
future: <Task finished name='Task-9' coro=<parse_games.<locals>.parsing() done, defined at C:\python_field\modules\scripts\async_featured_games.py:23> exception=KeyError('gameList')>
Traceback (most recent call last):
  File "C:\python_field\modules\scripts\async_featured_games.py", line 31, in parsing
    gameList = data['gameList']
               ~~~~^^^^^^^^^^^^
KeyError: 'gameList'
2023-11-06 10:25:56,719 ERROR Task exception was never retrieved
future: <Task finished name='Task-10' coro=<parse_games.<locals>.parsing() done, defined at C:\python_field\modules\scripts\async_featured_games.py:23> exception=KeyError('gameList')>
Traceback (most recent call last):
  File "C:\python_field\modules\scripts\async_featured_games.py", line 31, in parsing
    gameList = data['gameList']
               ~~~~^^^^^^^^^^^^
KeyError: 'gameList'
2023-11-16 22:44:38,500 ERROR list index out of range
Traceback (most recent call last):
  File "C:\python_field\MCF\mcf_riot_api.py", line 79, in wrapper
    result = func(*args, **kwargs)
             ^^^^^^^^^^^^^^^^^^^^^
  File "C:\python_field\MCF\mcf_riot_api.py", line 197, in get_poro_games
    ids = [int(str(ids.get('class')).split('-')[1]) for ids in game[0:5]]
          ^^^^^^^^^^^^^^^^^^^^^^^^^^^^^^^^^^^^^^^^^^^^^^^^^^^^^^^^^^^^^^^
  File "C:\python_field\MCF\mcf_riot_api.py", line 197, in <listcomp>
    ids = [int(str(ids.get('class')).split('-')[1]) for ids in game[0:5]]
               ~~~~~~~~~~~~~~~~~~~~~~~~~~~~~~~~^^^
IndexError: list index out of range
2023-11-16 22:44:42,363 ERROR list index out of range
Traceback (most recent call last):
  File "C:\python_field\MCF\mcf_riot_api.py", line 79, in wrapper
    result = func(*args, **kwargs)
             ^^^^^^^^^^^^^^^^^^^^^
  File "C:\python_field\MCF\mcf_riot_api.py", line 197, in get_poro_games
    ids = [int(str(ids.get('class')).split('-')[1]) for ids in game[0:5]]
          ^^^^^^^^^^^^^^^^^^^^^^^^^^^^^^^^^^^^^^^^^^^^^^^^^^^^^^^^^^^^^^^
  File "C:\python_field\MCF\mcf_riot_api.py", line 197, in <listcomp>
    ids = [int(str(ids.get('class')).split('-')[1]) for ids in game[0:5]]
               ~~~~~~~~~~~~~~~~~~~~~~~~~~~~~~~~^^^
IndexError: list index out of range
2023-11-16 22:44:55,852 ERROR list index out of range
Traceback (most recent call last):
  File "C:\python_field\MCF\mcf_riot_api.py", line 79, in wrapper
    result = func(*args, **kwargs)
             ^^^^^^^^^^^^^^^^^^^^^
  File "C:\python_field\MCF\mcf_riot_api.py", line 197, in get_poro_games
    ids = [int(str(ids.get('class')).split('-')[1]) for ids in game[0:5]]
          ^^^^^^^^^^^^^^^^^^^^^^^^^^^^^^^^^^^^^^^^^^^^^^^^^^^^^^^^^^^^^^^
  File "C:\python_field\MCF\mcf_riot_api.py", line 197, in <listcomp>
    ids = [int(str(ids.get('class')).split('-')[1]) for ids in game[0:5]]
               ~~~~~~~~~~~~~~~~~~~~~~~~~~~~~~~~^^^
IndexError: list index out of range
2023-11-16 22:46:38,814 ERROR list index out of range
Traceback (most recent call last):
  File "C:\python_field\MCF\mcf_riot_api.py", line 79, in wrapper
    result = func(*args, **kwargs)
             ^^^^^^^^^^^^^^^^^^^^^
  File "C:\python_field\MCF\mcf_riot_api.py", line 197, in get_poro_games
    ids = [int(str(ids.get('class')).split('-')[1]) for ids in game[0:5]]
          ^^^^^^^^^^^^^^^^^^^^^^^^^^^^^^^^^^^^^^^^^^^^^^^^^^^^^^^^^^^^^^^
  File "C:\python_field\MCF\mcf_riot_api.py", line 197, in <listcomp>
    ids = [int(str(ids.get('class')).split('-')[1]) for ids in game[0:5]]
               ~~~~~~~~~~~~~~~~~~~~~~~~~~~~~~~~^^^
IndexError: list index out of range
2023-11-16 22:46:55,332 ERROR list index out of range
Traceback (most recent call last):
  File "C:\python_field\MCF\mcf_riot_api.py", line 79, in wrapper
    result = func(*args, **kwargs)
             ^^^^^^^^^^^^^^^^^^^^^
  File "C:\python_field\MCF\mcf_riot_api.py", line 197, in get_poro_games
    ids = [int(str(ids.get('class')).split('-')[1]) for ids in game[0:5]]
          ^^^^^^^^^^^^^^^^^^^^^^^^^^^^^^^^^^^^^^^^^^^^^^^^^^^^^^^^^^^^^^^
  File "C:\python_field\MCF\mcf_riot_api.py", line 197, in <listcomp>
    ids = [int(str(ids.get('class')).split('-')[1]) for ids in game[0:5]]
               ~~~~~~~~~~~~~~~~~~~~~~~~~~~~~~~~^^^
IndexError: list index out of range
2023-11-17 20:33:05,123 ERROR HTTPSConnectionPool(host='sea.api.riotgames.com', port=443): Read timed out. (read timeout=3)
Traceback (most recent call last):
  File "C:\python_field\MCF\.mcfenv\Lib\site-packages\urllib3\connectionpool.py", line 386, in _make_request
    self._validate_conn(conn)
  File "C:\python_field\MCF\.mcfenv\Lib\site-packages\urllib3\connectionpool.py", line 1042, in _validate_conn
    conn.connect()
  File "C:\python_field\MCF\.mcfenv\Lib\site-packages\urllib3\connection.py", line 414, in connect
    self.sock = ssl_wrap_socket(
                ^^^^^^^^^^^^^^^^
  File "C:\python_field\MCF\.mcfenv\Lib\site-packages\urllib3\util\ssl_.py", line 449, in ssl_wrap_socket
    ssl_sock = _ssl_wrap_socket_impl(
               ^^^^^^^^^^^^^^^^^^^^^^
  File "C:\python_field\MCF\.mcfenv\Lib\site-packages\urllib3\util\ssl_.py", line 493, in _ssl_wrap_socket_impl
    return ssl_context.wrap_socket(sock, server_hostname=server_hostname)
           ^^^^^^^^^^^^^^^^^^^^^^^^^^^^^^^^^^^^^^^^^^^^^^^^^^^^^^^^^^^^^^
  File "C:\Users\New\AppData\Local\Programs\Python\Python311\Lib\ssl.py", line 517, in wrap_socket
    return self.sslsocket_class._create(
           ^^^^^^^^^^^^^^^^^^^^^^^^^^^^^
  File "C:\Users\New\AppData\Local\Programs\Python\Python311\Lib\ssl.py", line 1075, in _create
    self.do_handshake()
  File "C:\Users\New\AppData\Local\Programs\Python\Python311\Lib\ssl.py", line 1346, in do_handshake
    self._sslobj.do_handshake()
TimeoutError: _ssl.c:975: The handshake operation timed out

During handling of the above exception, another exception occurred:

Traceback (most recent call last):
  File "C:\python_field\MCF\.mcfenv\Lib\site-packages\requests\adapters.py", line 489, in send
    resp = conn.urlopen(
           ^^^^^^^^^^^^^
  File "C:\python_field\MCF\.mcfenv\Lib\site-packages\urllib3\connectionpool.py", line 787, in urlopen
    retries = retries.increment(
              ^^^^^^^^^^^^^^^^^^
  File "C:\python_field\MCF\.mcfenv\Lib\site-packages\urllib3\util\retry.py", line 550, in increment
    raise six.reraise(type(error), error, _stacktrace)
          ^^^^^^^^^^^^^^^^^^^^^^^^^^^^^^^^^^^^^^^^^^^^
  File "C:\python_field\MCF\.mcfenv\Lib\site-packages\urllib3\packages\six.py", line 770, in reraise
    raise value
  File "C:\python_field\MCF\.mcfenv\Lib\site-packages\urllib3\connectionpool.py", line 703, in urlopen
    httplib_response = self._make_request(
                       ^^^^^^^^^^^^^^^^^^^
  File "C:\python_field\MCF\.mcfenv\Lib\site-packages\urllib3\connectionpool.py", line 389, in _make_request
    self._raise_timeout(err=e, url=url, timeout_value=conn.timeout)
  File "C:\python_field\MCF\.mcfenv\Lib\site-packages\urllib3\connectionpool.py", line 340, in _raise_timeout
    raise ReadTimeoutError(
urllib3.exceptions.ReadTimeoutError: HTTPSConnectionPool(host='sea.api.riotgames.com', port=443): Read timed out. (read timeout=3)

During handling of the above exception, another exception occurred:

Traceback (most recent call last):
  File "C:\python_field\MCF\mcf_riot_api.py", line 79, in wrapper
    result = func(*args, **kwargs)
             ^^^^^^^^^^^^^^^^^^^^^
  File "C:\python_field\MCF\mcf_riot_api.py", line 113, in get_match_by_gameid
    result = requests.get(RiotAPI.__link_match_by_gameid.format(area=area, gameid=gameid),
            ^^^^^^^^^^^^^^^^^^^^^^^^^^^^^^^^^^^^^^^^^^^^^^^^^^^^^^^^^^^^^^^^^^^^^^^^^^^^^^
  File "C:\python_field\MCF\.mcfenv\Lib\site-packages\requests\api.py", line 73, in get
    return request("get", url, params=params, **kwargs)
           ^^^^^^^^^^^^^^^^^^^^^^^^^^^^^^^^^^^^^^^^^^^^
  File "C:\python_field\MCF\.mcfenv\Lib\site-packages\requests\api.py", line 59, in request
    return session.request(method=method, url=url, **kwargs)
           ^^^^^^^^^^^^^^^^^^^^^^^^^^^^^^^^^^^^^^^^^^^^^^^^^
  File "C:\python_field\MCF\.mcfenv\Lib\site-packages\requests\sessions.py", line 587, in request
    resp = self.send(prep, **send_kwargs)
           ^^^^^^^^^^^^^^^^^^^^^^^^^^^^^^
  File "C:\python_field\MCF\.mcfenv\Lib\site-packages\requests\sessions.py", line 701, in send
    r = adapter.send(request, **kwargs)
        ^^^^^^^^^^^^^^^^^^^^^^^^^^^^^^^
  File "C:\python_field\MCF\.mcfenv\Lib\site-packages\requests\adapters.py", line 578, in send
    raise ReadTimeout(e, request=request)
requests.exceptions.ReadTimeout: HTTPSConnectionPool(host='sea.api.riotgames.com', port=443): Read timed out. (read timeout=3)
2023-11-17 20:33:59,071 ERROR HTTPSConnectionPool(host='sea.api.riotgames.com', port=443): Read timed out. (read timeout=3)
Traceback (most recent call last):
  File "C:\python_field\MCF\.mcfenv\Lib\site-packages\urllib3\connectionpool.py", line 386, in _make_request
    self._validate_conn(conn)
  File "C:\python_field\MCF\.mcfenv\Lib\site-packages\urllib3\connectionpool.py", line 1042, in _validate_conn
    conn.connect()
  File "C:\python_field\MCF\.mcfenv\Lib\site-packages\urllib3\connection.py", line 414, in connect
    self.sock = ssl_wrap_socket(
                ^^^^^^^^^^^^^^^^
  File "C:\python_field\MCF\.mcfenv\Lib\site-packages\urllib3\util\ssl_.py", line 449, in ssl_wrap_socket
    ssl_sock = _ssl_wrap_socket_impl(
               ^^^^^^^^^^^^^^^^^^^^^^
  File "C:\python_field\MCF\.mcfenv\Lib\site-packages\urllib3\util\ssl_.py", line 493, in _ssl_wrap_socket_impl
    return ssl_context.wrap_socket(sock, server_hostname=server_hostname)
           ^^^^^^^^^^^^^^^^^^^^^^^^^^^^^^^^^^^^^^^^^^^^^^^^^^^^^^^^^^^^^^
  File "C:\Users\New\AppData\Local\Programs\Python\Python311\Lib\ssl.py", line 517, in wrap_socket
    return self.sslsocket_class._create(
           ^^^^^^^^^^^^^^^^^^^^^^^^^^^^^
  File "C:\Users\New\AppData\Local\Programs\Python\Python311\Lib\ssl.py", line 1075, in _create
    self.do_handshake()
  File "C:\Users\New\AppData\Local\Programs\Python\Python311\Lib\ssl.py", line 1346, in do_handshake
    self._sslobj.do_handshake()
TimeoutError: _ssl.c:975: The handshake operation timed out

During handling of the above exception, another exception occurred:

Traceback (most recent call last):
  File "C:\python_field\MCF\.mcfenv\Lib\site-packages\requests\adapters.py", line 489, in send
    resp = conn.urlopen(
           ^^^^^^^^^^^^^
  File "C:\python_field\MCF\.mcfenv\Lib\site-packages\urllib3\connectionpool.py", line 787, in urlopen
    retries = retries.increment(
              ^^^^^^^^^^^^^^^^^^
  File "C:\python_field\MCF\.mcfenv\Lib\site-packages\urllib3\util\retry.py", line 550, in increment
    raise six.reraise(type(error), error, _stacktrace)
          ^^^^^^^^^^^^^^^^^^^^^^^^^^^^^^^^^^^^^^^^^^^^
  File "C:\python_field\MCF\.mcfenv\Lib\site-packages\urllib3\packages\six.py", line 770, in reraise
    raise value
  File "C:\python_field\MCF\.mcfenv\Lib\site-packages\urllib3\connectionpool.py", line 703, in urlopen
    httplib_response = self._make_request(
                       ^^^^^^^^^^^^^^^^^^^
  File "C:\python_field\MCF\.mcfenv\Lib\site-packages\urllib3\connectionpool.py", line 389, in _make_request
    self._raise_timeout(err=e, url=url, timeout_value=conn.timeout)
  File "C:\python_field\MCF\.mcfenv\Lib\site-packages\urllib3\connectionpool.py", line 340, in _raise_timeout
    raise ReadTimeoutError(
urllib3.exceptions.ReadTimeoutError: HTTPSConnectionPool(host='sea.api.riotgames.com', port=443): Read timed out. (read timeout=3)

During handling of the above exception, another exception occurred:

Traceback (most recent call last):
  File "C:\python_field\MCF\mcf_riot_api.py", line 79, in wrapper
    result = func(*args, **kwargs)
             ^^^^^^^^^^^^^^^^^^^^^
  File "C:\python_field\MCF\mcf_riot_api.py", line 113, in get_match_by_gameid
    result = requests.get(RiotAPI.__link_match_by_gameid.format(area=area, gameid=gameid),
            ^^^^^^^^^^^^^^^^^^^^^^^^^^^^^^^^^^^^^^^^^^^^^^^^^^^^^^^^^^^^^^^^^^^^^^^^^^^^^^
  File "C:\python_field\MCF\.mcfenv\Lib\site-packages\requests\api.py", line 73, in get
    return request("get", url, params=params, **kwargs)
           ^^^^^^^^^^^^^^^^^^^^^^^^^^^^^^^^^^^^^^^^^^^^
  File "C:\python_field\MCF\.mcfenv\Lib\site-packages\requests\api.py", line 59, in request
    return session.request(method=method, url=url, **kwargs)
           ^^^^^^^^^^^^^^^^^^^^^^^^^^^^^^^^^^^^^^^^^^^^^^^^^
  File "C:\python_field\MCF\.mcfenv\Lib\site-packages\requests\sessions.py", line 587, in request
    resp = self.send(prep, **send_kwargs)
           ^^^^^^^^^^^^^^^^^^^^^^^^^^^^^^
  File "C:\python_field\MCF\.mcfenv\Lib\site-packages\requests\sessions.py", line 701, in send
    r = adapter.send(request, **kwargs)
        ^^^^^^^^^^^^^^^^^^^^^^^^^^^^^^^
  File "C:\python_field\MCF\.mcfenv\Lib\site-packages\requests\adapters.py", line 578, in send
    raise ReadTimeout(e, request=request)
requests.exceptions.ReadTimeout: HTTPSConnectionPool(host='sea.api.riotgames.com', port=443): Read timed out. (read timeout=3)
2023-11-17 20:35:26,309 ERROR HTTPSConnectionPool(host='sea.api.riotgames.com', port=443): Read timed out. (read timeout=3)
Traceback (most recent call last):
  File "C:\python_field\MCF\.mcfenv\Lib\site-packages\urllib3\connectionpool.py", line 386, in _make_request
    self._validate_conn(conn)
  File "C:\python_field\MCF\.mcfenv\Lib\site-packages\urllib3\connectionpool.py", line 1042, in _validate_conn
    conn.connect()
  File "C:\python_field\MCF\.mcfenv\Lib\site-packages\urllib3\connection.py", line 414, in connect
    self.sock = ssl_wrap_socket(
                ^^^^^^^^^^^^^^^^
  File "C:\python_field\MCF\.mcfenv\Lib\site-packages\urllib3\util\ssl_.py", line 449, in ssl_wrap_socket
    ssl_sock = _ssl_wrap_socket_impl(
               ^^^^^^^^^^^^^^^^^^^^^^
  File "C:\python_field\MCF\.mcfenv\Lib\site-packages\urllib3\util\ssl_.py", line 493, in _ssl_wrap_socket_impl
    return ssl_context.wrap_socket(sock, server_hostname=server_hostname)
           ^^^^^^^^^^^^^^^^^^^^^^^^^^^^^^^^^^^^^^^^^^^^^^^^^^^^^^^^^^^^^^
  File "C:\Users\New\AppData\Local\Programs\Python\Python311\Lib\ssl.py", line 517, in wrap_socket
    return self.sslsocket_class._create(
           ^^^^^^^^^^^^^^^^^^^^^^^^^^^^^
  File "C:\Users\New\AppData\Local\Programs\Python\Python311\Lib\ssl.py", line 1075, in _create
    self.do_handshake()
  File "C:\Users\New\AppData\Local\Programs\Python\Python311\Lib\ssl.py", line 1346, in do_handshake
    self._sslobj.do_handshake()
TimeoutError: _ssl.c:975: The handshake operation timed out

During handling of the above exception, another exception occurred:

Traceback (most recent call last):
  File "C:\python_field\MCF\.mcfenv\Lib\site-packages\requests\adapters.py", line 489, in send
    resp = conn.urlopen(
           ^^^^^^^^^^^^^
  File "C:\python_field\MCF\.mcfenv\Lib\site-packages\urllib3\connectionpool.py", line 787, in urlopen
    retries = retries.increment(
              ^^^^^^^^^^^^^^^^^^
  File "C:\python_field\MCF\.mcfenv\Lib\site-packages\urllib3\util\retry.py", line 550, in increment
    raise six.reraise(type(error), error, _stacktrace)
          ^^^^^^^^^^^^^^^^^^^^^^^^^^^^^^^^^^^^^^^^^^^^
  File "C:\python_field\MCF\.mcfenv\Lib\site-packages\urllib3\packages\six.py", line 770, in reraise
    raise value
  File "C:\python_field\MCF\.mcfenv\Lib\site-packages\urllib3\connectionpool.py", line 703, in urlopen
    httplib_response = self._make_request(
                       ^^^^^^^^^^^^^^^^^^^
  File "C:\python_field\MCF\.mcfenv\Lib\site-packages\urllib3\connectionpool.py", line 389, in _make_request
    self._raise_timeout(err=e, url=url, timeout_value=conn.timeout)
  File "C:\python_field\MCF\.mcfenv\Lib\site-packages\urllib3\connectionpool.py", line 340, in _raise_timeout
    raise ReadTimeoutError(
urllib3.exceptions.ReadTimeoutError: HTTPSConnectionPool(host='sea.api.riotgames.com', port=443): Read timed out. (read timeout=3)

During handling of the above exception, another exception occurred:

Traceback (most recent call last):
  File "C:\python_field\MCF\mcf_riot_api.py", line 79, in wrapper
    result = func(*args, **kwargs)
             ^^^^^^^^^^^^^^^^^^^^^
  File "C:\python_field\MCF\mcf_riot_api.py", line 113, in get_match_by_gameid
    result = requests.get(RiotAPI.__link_match_by_gameid.format(area=area, gameid=gameid),
            ^^^^^^^^^^^^^^^^^^^^^^^^^^^^^^^^^^^^^^^^^^^^^^^^^^^^^^^^^^^^^^^^^^^^^^^^^^^^^^
  File "C:\python_field\MCF\.mcfenv\Lib\site-packages\requests\api.py", line 73, in get
    return request("get", url, params=params, **kwargs)
           ^^^^^^^^^^^^^^^^^^^^^^^^^^^^^^^^^^^^^^^^^^^^
  File "C:\python_field\MCF\.mcfenv\Lib\site-packages\requests\api.py", line 59, in request
    return session.request(method=method, url=url, **kwargs)
           ^^^^^^^^^^^^^^^^^^^^^^^^^^^^^^^^^^^^^^^^^^^^^^^^^
  File "C:\python_field\MCF\.mcfenv\Lib\site-packages\requests\sessions.py", line 587, in request
    resp = self.send(prep, **send_kwargs)
           ^^^^^^^^^^^^^^^^^^^^^^^^^^^^^^
  File "C:\python_field\MCF\.mcfenv\Lib\site-packages\requests\sessions.py", line 701, in send
    r = adapter.send(request, **kwargs)
        ^^^^^^^^^^^^^^^^^^^^^^^^^^^^^^^
  File "C:\python_field\MCF\.mcfenv\Lib\site-packages\requests\adapters.py", line 578, in send
    raise ReadTimeout(e, request=request)
requests.exceptions.ReadTimeout: HTTPSConnectionPool(host='sea.api.riotgames.com', port=443): Read timed out. (read timeout=3)
2023-11-17 21:12:03,067 ERROR HTTPSConnectionPool(host='asia.api.riotgames.com', port=443): Read timed out. (read timeout=3)
Traceback (most recent call last):
  File "C:\python_field\MCF\.mcfenv\Lib\site-packages\urllib3\connectionpool.py", line 449, in _make_request
    six.raise_from(e, None)
  File "<string>", line 3, in raise_from
  File "C:\python_field\MCF\.mcfenv\Lib\site-packages\urllib3\connectionpool.py", line 444, in _make_request
    httplib_response = conn.getresponse()
                       ^^^^^^^^^^^^^^^^^^
  File "C:\Users\New\AppData\Local\Programs\Python\Python311\Lib\http\client.py", line 1374, in getresponse
    response.begin()
  File "C:\Users\New\AppData\Local\Programs\Python\Python311\Lib\http\client.py", line 318, in begin
    version, status, reason = self._read_status()
                              ^^^^^^^^^^^^^^^^^^^
  File "C:\Users\New\AppData\Local\Programs\Python\Python311\Lib\http\client.py", line 279, in _read_status
    line = str(self.fp.readline(_MAXLINE + 1), "iso-8859-1")
               ^^^^^^^^^^^^^^^^^^^^^^^^^^^^^^
  File "C:\Users\New\AppData\Local\Programs\Python\Python311\Lib\socket.py", line 705, in readinto
    return self._sock.recv_into(b)
           ^^^^^^^^^^^^^^^^^^^^^^^
  File "C:\Users\New\AppData\Local\Programs\Python\Python311\Lib\ssl.py", line 1278, in recv_into
    return self.read(nbytes, buffer)
           ^^^^^^^^^^^^^^^^^^^^^^^^^
  File "C:\Users\New\AppData\Local\Programs\Python\Python311\Lib\ssl.py", line 1134, in read
    return self._sslobj.read(len, buffer)
           ^^^^^^^^^^^^^^^^^^^^^^^^^^^^^^
TimeoutError: The read operation timed out

During handling of the above exception, another exception occurred:

Traceback (most recent call last):
  File "C:\python_field\MCF\.mcfenv\Lib\site-packages\requests\adapters.py", line 489, in send
    resp = conn.urlopen(
           ^^^^^^^^^^^^^
  File "C:\python_field\MCF\.mcfenv\Lib\site-packages\urllib3\connectionpool.py", line 787, in urlopen
    retries = retries.increment(
              ^^^^^^^^^^^^^^^^^^
  File "C:\python_field\MCF\.mcfenv\Lib\site-packages\urllib3\util\retry.py", line 550, in increment
    raise six.reraise(type(error), error, _stacktrace)
          ^^^^^^^^^^^^^^^^^^^^^^^^^^^^^^^^^^^^^^^^^^^^
  File "C:\python_field\MCF\.mcfenv\Lib\site-packages\urllib3\packages\six.py", line 770, in reraise
    raise value
  File "C:\python_field\MCF\.mcfenv\Lib\site-packages\urllib3\connectionpool.py", line 703, in urlopen
    httplib_response = self._make_request(
                       ^^^^^^^^^^^^^^^^^^^
  File "C:\python_field\MCF\.mcfenv\Lib\site-packages\urllib3\connectionpool.py", line 451, in _make_request
    self._raise_timeout(err=e, url=url, timeout_value=read_timeout)
  File "C:\python_field\MCF\.mcfenv\Lib\site-packages\urllib3\connectionpool.py", line 340, in _raise_timeout
    raise ReadTimeoutError(
urllib3.exceptions.ReadTimeoutError: HTTPSConnectionPool(host='asia.api.riotgames.com', port=443): Read timed out. (read timeout=3)

During handling of the above exception, another exception occurred:

Traceback (most recent call last):
  File "C:\python_field\MCF\mcf_riot_api.py", line 79, in wrapper
    result = func(*args, **kwargs)
             ^^^^^^^^^^^^^^^^^^^^^
  File "C:\python_field\MCF\mcf_riot_api.py", line 113, in get_match_by_gameid
    result = requests.get(RiotAPI.__link_match_by_gameid.format(area=area, gameid=gameid),
            ^^^^^^^^^^^^^^^^^^^^^^^^^^^^^^^^^^^^^^^^^^^^^^^^^^^^^^^^^^^^^^^^^^^^^^^^^^^^^^
  File "C:\python_field\MCF\.mcfenv\Lib\site-packages\requests\api.py", line 73, in get
    return request("get", url, params=params, **kwargs)
           ^^^^^^^^^^^^^^^^^^^^^^^^^^^^^^^^^^^^^^^^^^^^
  File "C:\python_field\MCF\.mcfenv\Lib\site-packages\requests\api.py", line 59, in request
    return session.request(method=method, url=url, **kwargs)
           ^^^^^^^^^^^^^^^^^^^^^^^^^^^^^^^^^^^^^^^^^^^^^^^^^
  File "C:\python_field\MCF\.mcfenv\Lib\site-packages\requests\sessions.py", line 587, in request
    resp = self.send(prep, **send_kwargs)
           ^^^^^^^^^^^^^^^^^^^^^^^^^^^^^^
  File "C:\python_field\MCF\.mcfenv\Lib\site-packages\requests\sessions.py", line 701, in send
    r = adapter.send(request, **kwargs)
        ^^^^^^^^^^^^^^^^^^^^^^^^^^^^^^^
  File "C:\python_field\MCF\.mcfenv\Lib\site-packages\requests\adapters.py", line 578, in send
    raise ReadTimeout(e, request=request)
requests.exceptions.ReadTimeout: HTTPSConnectionPool(host='asia.api.riotgames.com', port=443): Read timed out. (read timeout=3)
2023-11-17 21:14:26,981 ERROR HTTPSConnectionPool(host='asia.api.riotgames.com', port=443): Read timed out. (read timeout=3)
Traceback (most recent call last):
  File "C:\python_field\MCF\.mcfenv\Lib\site-packages\urllib3\connectionpool.py", line 386, in _make_request
    self._validate_conn(conn)
  File "C:\python_field\MCF\.mcfenv\Lib\site-packages\urllib3\connectionpool.py", line 1042, in _validate_conn
    conn.connect()
  File "C:\python_field\MCF\.mcfenv\Lib\site-packages\urllib3\connection.py", line 414, in connect
    self.sock = ssl_wrap_socket(
                ^^^^^^^^^^^^^^^^
  File "C:\python_field\MCF\.mcfenv\Lib\site-packages\urllib3\util\ssl_.py", line 449, in ssl_wrap_socket
    ssl_sock = _ssl_wrap_socket_impl(
               ^^^^^^^^^^^^^^^^^^^^^^
  File "C:\python_field\MCF\.mcfenv\Lib\site-packages\urllib3\util\ssl_.py", line 493, in _ssl_wrap_socket_impl
    return ssl_context.wrap_socket(sock, server_hostname=server_hostname)
           ^^^^^^^^^^^^^^^^^^^^^^^^^^^^^^^^^^^^^^^^^^^^^^^^^^^^^^^^^^^^^^
  File "C:\Users\New\AppData\Local\Programs\Python\Python311\Lib\ssl.py", line 517, in wrap_socket
    return self.sslsocket_class._create(
           ^^^^^^^^^^^^^^^^^^^^^^^^^^^^^
  File "C:\Users\New\AppData\Local\Programs\Python\Python311\Lib\ssl.py", line 1075, in _create
    self.do_handshake()
  File "C:\Users\New\AppData\Local\Programs\Python\Python311\Lib\ssl.py", line 1346, in do_handshake
    self._sslobj.do_handshake()
TimeoutError: _ssl.c:975: The handshake operation timed out

During handling of the above exception, another exception occurred:

Traceback (most recent call last):
  File "C:\python_field\MCF\.mcfenv\Lib\site-packages\requests\adapters.py", line 489, in send
    resp = conn.urlopen(
           ^^^^^^^^^^^^^
  File "C:\python_field\MCF\.mcfenv\Lib\site-packages\urllib3\connectionpool.py", line 787, in urlopen
    retries = retries.increment(
              ^^^^^^^^^^^^^^^^^^
  File "C:\python_field\MCF\.mcfenv\Lib\site-packages\urllib3\util\retry.py", line 550, in increment
    raise six.reraise(type(error), error, _stacktrace)
          ^^^^^^^^^^^^^^^^^^^^^^^^^^^^^^^^^^^^^^^^^^^^
  File "C:\python_field\MCF\.mcfenv\Lib\site-packages\urllib3\packages\six.py", line 770, in reraise
    raise value
  File "C:\python_field\MCF\.mcfenv\Lib\site-packages\urllib3\connectionpool.py", line 703, in urlopen
    httplib_response = self._make_request(
                       ^^^^^^^^^^^^^^^^^^^
  File "C:\python_field\MCF\.mcfenv\Lib\site-packages\urllib3\connectionpool.py", line 389, in _make_request
    self._raise_timeout(err=e, url=url, timeout_value=conn.timeout)
  File "C:\python_field\MCF\.mcfenv\Lib\site-packages\urllib3\connectionpool.py", line 340, in _raise_timeout
    raise ReadTimeoutError(
urllib3.exceptions.ReadTimeoutError: HTTPSConnectionPool(host='asia.api.riotgames.com', port=443): Read timed out. (read timeout=3)

During handling of the above exception, another exception occurred:

Traceback (most recent call last):
  File "C:\python_field\MCF\mcf_riot_api.py", line 79, in wrapper
    result = func(*args, **kwargs)
             ^^^^^^^^^^^^^^^^^^^^^
  File "C:\python_field\MCF\mcf_riot_api.py", line 113, in get_match_by_gameid
    result = requests.get(RiotAPI.__link_match_by_gameid.format(area=area, gameid=gameid),
            ^^^^^^^^^^^^^^^^^^^^^^^^^^^^^^^^^^^^^^^^^^^^^^^^^^^^^^^^^^^^^^^^^^^^^^^^^^^^^^
  File "C:\python_field\MCF\.mcfenv\Lib\site-packages\requests\api.py", line 73, in get
    return request("get", url, params=params, **kwargs)
           ^^^^^^^^^^^^^^^^^^^^^^^^^^^^^^^^^^^^^^^^^^^^
  File "C:\python_field\MCF\.mcfenv\Lib\site-packages\requests\api.py", line 59, in request
    return session.request(method=method, url=url, **kwargs)
           ^^^^^^^^^^^^^^^^^^^^^^^^^^^^^^^^^^^^^^^^^^^^^^^^^
  File "C:\python_field\MCF\.mcfenv\Lib\site-packages\requests\sessions.py", line 587, in request
    resp = self.send(prep, **send_kwargs)
           ^^^^^^^^^^^^^^^^^^^^^^^^^^^^^^
  File "C:\python_field\MCF\.mcfenv\Lib\site-packages\requests\sessions.py", line 701, in send
    r = adapter.send(request, **kwargs)
        ^^^^^^^^^^^^^^^^^^^^^^^^^^^^^^^
  File "C:\python_field\MCF\.mcfenv\Lib\site-packages\requests\adapters.py", line 578, in send
    raise ReadTimeout(e, request=request)
requests.exceptions.ReadTimeout: HTTPSConnectionPool(host='asia.api.riotgames.com', port=443): Read timed out. (read timeout=3)
2023-11-17 21:17:06,620 ERROR HTTPSConnectionPool(host='asia.api.riotgames.com', port=443): Read timed out. (read timeout=3)
Traceback (most recent call last):
  File "C:\python_field\MCF\.mcfenv\Lib\site-packages\urllib3\connectionpool.py", line 386, in _make_request
    self._validate_conn(conn)
  File "C:\python_field\MCF\.mcfenv\Lib\site-packages\urllib3\connectionpool.py", line 1042, in _validate_conn
    conn.connect()
  File "C:\python_field\MCF\.mcfenv\Lib\site-packages\urllib3\connection.py", line 414, in connect
    self.sock = ssl_wrap_socket(
                ^^^^^^^^^^^^^^^^
  File "C:\python_field\MCF\.mcfenv\Lib\site-packages\urllib3\util\ssl_.py", line 449, in ssl_wrap_socket
    ssl_sock = _ssl_wrap_socket_impl(
               ^^^^^^^^^^^^^^^^^^^^^^
  File "C:\python_field\MCF\.mcfenv\Lib\site-packages\urllib3\util\ssl_.py", line 493, in _ssl_wrap_socket_impl
    return ssl_context.wrap_socket(sock, server_hostname=server_hostname)
           ^^^^^^^^^^^^^^^^^^^^^^^^^^^^^^^^^^^^^^^^^^^^^^^^^^^^^^^^^^^^^^
  File "C:\Users\New\AppData\Local\Programs\Python\Python311\Lib\ssl.py", line 517, in wrap_socket
    return self.sslsocket_class._create(
           ^^^^^^^^^^^^^^^^^^^^^^^^^^^^^
  File "C:\Users\New\AppData\Local\Programs\Python\Python311\Lib\ssl.py", line 1075, in _create
    self.do_handshake()
  File "C:\Users\New\AppData\Local\Programs\Python\Python311\Lib\ssl.py", line 1346, in do_handshake
    self._sslobj.do_handshake()
TimeoutError: _ssl.c:975: The handshake operation timed out

During handling of the above exception, another exception occurred:

Traceback (most recent call last):
  File "C:\python_field\MCF\.mcfenv\Lib\site-packages\requests\adapters.py", line 489, in send
    resp = conn.urlopen(
           ^^^^^^^^^^^^^
  File "C:\python_field\MCF\.mcfenv\Lib\site-packages\urllib3\connectionpool.py", line 787, in urlopen
    retries = retries.increment(
              ^^^^^^^^^^^^^^^^^^
  File "C:\python_field\MCF\.mcfenv\Lib\site-packages\urllib3\util\retry.py", line 550, in increment
    raise six.reraise(type(error), error, _stacktrace)
          ^^^^^^^^^^^^^^^^^^^^^^^^^^^^^^^^^^^^^^^^^^^^
  File "C:\python_field\MCF\.mcfenv\Lib\site-packages\urllib3\packages\six.py", line 770, in reraise
    raise value
  File "C:\python_field\MCF\.mcfenv\Lib\site-packages\urllib3\connectionpool.py", line 703, in urlopen
    httplib_response = self._make_request(
                       ^^^^^^^^^^^^^^^^^^^
  File "C:\python_field\MCF\.mcfenv\Lib\site-packages\urllib3\connectionpool.py", line 389, in _make_request
    self._raise_timeout(err=e, url=url, timeout_value=conn.timeout)
  File "C:\python_field\MCF\.mcfenv\Lib\site-packages\urllib3\connectionpool.py", line 340, in _raise_timeout
    raise ReadTimeoutError(
urllib3.exceptions.ReadTimeoutError: HTTPSConnectionPool(host='asia.api.riotgames.com', port=443): Read timed out. (read timeout=3)

During handling of the above exception, another exception occurred:

Traceback (most recent call last):
  File "C:\python_field\MCF\mcf_riot_api.py", line 79, in wrapper
    result = func(*args, **kwargs)
             ^^^^^^^^^^^^^^^^^^^^^
  File "C:\python_field\MCF\mcf_riot_api.py", line 113, in get_match_by_gameid
    result = requests.get(RiotAPI.__link_match_by_gameid.format(area=area, gameid=gameid),
            ^^^^^^^^^^^^^^^^^^^^^^^^^^^^^^^^^^^^^^^^^^^^^^^^^^^^^^^^^^^^^^^^^^^^^^^^^^^^^^
  File "C:\python_field\MCF\.mcfenv\Lib\site-packages\requests\api.py", line 73, in get
    return request("get", url, params=params, **kwargs)
           ^^^^^^^^^^^^^^^^^^^^^^^^^^^^^^^^^^^^^^^^^^^^
  File "C:\python_field\MCF\.mcfenv\Lib\site-packages\requests\api.py", line 59, in request
    return session.request(method=method, url=url, **kwargs)
           ^^^^^^^^^^^^^^^^^^^^^^^^^^^^^^^^^^^^^^^^^^^^^^^^^
  File "C:\python_field\MCF\.mcfenv\Lib\site-packages\requests\sessions.py", line 587, in request
    resp = self.send(prep, **send_kwargs)
           ^^^^^^^^^^^^^^^^^^^^^^^^^^^^^^
  File "C:\python_field\MCF\.mcfenv\Lib\site-packages\requests\sessions.py", line 701, in send
    r = adapter.send(request, **kwargs)
        ^^^^^^^^^^^^^^^^^^^^^^^^^^^^^^^
  File "C:\python_field\MCF\.mcfenv\Lib\site-packages\requests\adapters.py", line 578, in send
    raise ReadTimeout(e, request=request)
requests.exceptions.ReadTimeout: HTTPSConnectionPool(host='asia.api.riotgames.com', port=443): Read timed out. (read timeout=3)
2023-11-19 19:23:52,071 ERROR list index out of range
Traceback (most recent call last):
  File "C:\python_field\MCF\mcf_riot_api.py", line 87, in wrapper
    result = func(*args, **kwargs)
             ^^^^^^^^^^^^^^^^^^^^^
  File "C:\python_field\MCF\mcf_riot_api.py", line 206, in get_poro_games
    ids = [int(str(ids.get('class')).split('-')[1]) for ids in game[0:5]]
          ^^^^^^^^^^^^^^^^^^^^^^^^^^^^^^^^^^^^^^^^^^^^^^^^^^^^^^^^^^^^^^^
  File "C:\python_field\MCF\mcf_riot_api.py", line 206, in <listcomp>
    ids = [int(str(ids.get('class')).split('-')[1]) for ids in game[0:5]]
               ~~~~~~~~~~~~~~~~~~~~~~~~~~~~~~~~^^^
IndexError: list index out of range
2023-11-19 19:23:54,381 ERROR list index out of range
Traceback (most recent call last):
  File "C:\python_field\MCF\mcf_riot_api.py", line 87, in wrapper
    result = func(*args, **kwargs)
             ^^^^^^^^^^^^^^^^^^^^^
  File "C:\python_field\MCF\mcf_riot_api.py", line 206, in get_poro_games
    ids = [int(str(ids.get('class')).split('-')[1]) for ids in game[0:5]]
          ^^^^^^^^^^^^^^^^^^^^^^^^^^^^^^^^^^^^^^^^^^^^^^^^^^^^^^^^^^^^^^^
  File "C:\python_field\MCF\mcf_riot_api.py", line 206, in <listcomp>
    ids = [int(str(ids.get('class')).split('-')[1]) for ids in game[0:5]]
               ~~~~~~~~~~~~~~~~~~~~~~~~~~~~~~~~^^^
IndexError: list index out of range
2023-11-19 19:24:00,028 ERROR list index out of range
Traceback (most recent call last):
  File "C:\python_field\MCF\mcf_riot_api.py", line 87, in wrapper
    result = func(*args, **kwargs)
             ^^^^^^^^^^^^^^^^^^^^^
  File "C:\python_field\MCF\mcf_riot_api.py", line 206, in get_poro_games
    ids = [int(str(ids.get('class')).split('-')[1]) for ids in game[0:5]]
          ^^^^^^^^^^^^^^^^^^^^^^^^^^^^^^^^^^^^^^^^^^^^^^^^^^^^^^^^^^^^^^^
  File "C:\python_field\MCF\mcf_riot_api.py", line 206, in <listcomp>
    ids = [int(str(ids.get('class')).split('-')[1]) for ids in game[0:5]]
               ~~~~~~~~~~~~~~~~~~~~~~~~~~~~~~~~^^^
IndexError: list index out of range
2023-11-20 18:34:08,781 ERROR list index out of range
Traceback (most recent call last):
  File "C:\python_field\MCF\mcf_riot_api.py", line 87, in wrapper
    result = func(*args, **kwargs)
             ^^^^^^^^^^^^^^^^^^^^^
  File "C:\python_field\MCF\mcf_riot_api.py", line 206, in get_poro_games
    ids = [int(str(ids.get('class')).split('-')[1]) for ids in game[0:5]]
          ^^^^^^^^^^^^^^^^^^^^^^^^^^^^^^^^^^^^^^^^^^^^^^^^^^^^^^^^^^^^^^^
  File "C:\python_field\MCF\mcf_riot_api.py", line 206, in <listcomp>
    ids = [int(str(ids.get('class')).split('-')[1]) for ids in game[0:5]]
               ~~~~~~~~~~~~~~~~~~~~~~~~~~~~~~~~^^^
IndexError: list index out of range
2023-11-20 20:59:16,642 ERROR list index out of range
Traceback (most recent call last):
  File "C:\python_field\MCF\mcf_riot_api.py", line 87, in wrapper
    result = func(*args, **kwargs)
             ^^^^^^^^^^^^^^^^^^^^^
  File "C:\python_field\MCF\mcf_riot_api.py", line 206, in get_poro_games
    ids = [int(str(ids.get('class')).split('-')[1]) for ids in game[0:5]]
          ^^^^^^^^^^^^^^^^^^^^^^^^^^^^^^^^^^^^^^^^^^^^^^^^^^^^^^^^^^^^^^^
  File "C:\python_field\MCF\mcf_riot_api.py", line 206, in <listcomp>
    ids = [int(str(ids.get('class')).split('-')[1]) for ids in game[0:5]]
               ~~~~~~~~~~~~~~~~~~~~~~~~~~~~~~~~^^^
IndexError: list index out of range
2023-11-20 20:59:19,339 ERROR list index out of range
Traceback (most recent call last):
  File "C:\python_field\MCF\mcf_riot_api.py", line 87, in wrapper
    result = func(*args, **kwargs)
             ^^^^^^^^^^^^^^^^^^^^^
  File "C:\python_field\MCF\mcf_riot_api.py", line 206, in get_poro_games
    ids = [int(str(ids.get('class')).split('-')[1]) for ids in game[0:5]]
          ^^^^^^^^^^^^^^^^^^^^^^^^^^^^^^^^^^^^^^^^^^^^^^^^^^^^^^^^^^^^^^^
  File "C:\python_field\MCF\mcf_riot_api.py", line 206, in <listcomp>
    ids = [int(str(ids.get('class')).split('-')[1]) for ids in game[0:5]]
               ~~~~~~~~~~~~~~~~~~~~~~~~~~~~~~~~^^^
IndexError: list index out of range
2023-11-20 20:59:22,495 ERROR list index out of range
Traceback (most recent call last):
  File "C:\python_field\MCF\mcf_riot_api.py", line 87, in wrapper
    result = func(*args, **kwargs)
             ^^^^^^^^^^^^^^^^^^^^^
  File "C:\python_field\MCF\mcf_riot_api.py", line 206, in get_poro_games
    ids = [int(str(ids.get('class')).split('-')[1]) for ids in game[0:5]]
          ^^^^^^^^^^^^^^^^^^^^^^^^^^^^^^^^^^^^^^^^^^^^^^^^^^^^^^^^^^^^^^^
  File "C:\python_field\MCF\mcf_riot_api.py", line 206, in <listcomp>
    ids = [int(str(ids.get('class')).split('-')[1]) for ids in game[0:5]]
               ~~~~~~~~~~~~~~~~~~~~~~~~~~~~~~~~^^^
IndexError: list index out of range
2023-11-20 23:36:13,116 ERROR list index out of range
Traceback (most recent call last):
  File "C:\python_field\MCF\mcf_riot_api.py", line 87, in wrapper
    result = func(*args, **kwargs)
             ^^^^^^^^^^^^^^^^^^^^^
  File "C:\python_field\MCF\mcf_riot_api.py", line 206, in get_poro_games
    ids = [int(str(ids.get('class')).split('-')[1]) for ids in game[0:5]]
          ^^^^^^^^^^^^^^^^^^^^^^^^^^^^^^^^^^^^^^^^^^^^^^^^^^^^^^^^^^^^^^^
  File "C:\python_field\MCF\mcf_riot_api.py", line 206, in <listcomp>
    ids = [int(str(ids.get('class')).split('-')[1]) for ids in game[0:5]]
               ~~~~~~~~~~~~~~~~~~~~~~~~~~~~~~~~^^^
IndexError: list index out of range
2023-11-21 19:30:17,539 ERROR list index out of range
Traceback (most recent call last):
  File "C:\python_field\MCF\mcf_riot_api.py", line 87, in wrapper
    result = func(*args, **kwargs)
             ^^^^^^^^^^^^^^^^^^^^^
  File "C:\python_field\MCF\mcf_riot_api.py", line 206, in get_poro_games
    ids = [int(str(ids.get('class')).split('-')[1]) for ids in game[0:5]]
          ^^^^^^^^^^^^^^^^^^^^^^^^^^^^^^^^^^^^^^^^^^^^^^^^^^^^^^^^^^^^^^^
  File "C:\python_field\MCF\mcf_riot_api.py", line 206, in <listcomp>
    ids = [int(str(ids.get('class')).split('-')[1]) for ids in game[0:5]]
               ~~~~~~~~~~~~~~~~~~~~~~~~~~~~~~~~^^^
IndexError: list index out of range
2023-11-21 19:30:22,585 ERROR list index out of range
Traceback (most recent call last):
  File "C:\python_field\MCF\mcf_riot_api.py", line 87, in wrapper
    result = func(*args, **kwargs)
             ^^^^^^^^^^^^^^^^^^^^^
  File "C:\python_field\MCF\mcf_riot_api.py", line 206, in get_poro_games
    ids = [int(str(ids.get('class')).split('-')[1]) for ids in game[0:5]]
          ^^^^^^^^^^^^^^^^^^^^^^^^^^^^^^^^^^^^^^^^^^^^^^^^^^^^^^^^^^^^^^^
  File "C:\python_field\MCF\mcf_riot_api.py", line 206, in <listcomp>
    ids = [int(str(ids.get('class')).split('-')[1]) for ids in game[0:5]]
               ~~~~~~~~~~~~~~~~~~~~~~~~~~~~~~~~^^^
IndexError: list index out of range
2023-11-21 19:30:35,778 ERROR list index out of range
Traceback (most recent call last):
  File "C:\python_field\MCF\mcf_riot_api.py", line 87, in wrapper
    result = func(*args, **kwargs)
             ^^^^^^^^^^^^^^^^^^^^^
  File "C:\python_field\MCF\mcf_riot_api.py", line 206, in get_poro_games
    ids = [int(str(ids.get('class')).split('-')[1]) for ids in game[0:5]]
          ^^^^^^^^^^^^^^^^^^^^^^^^^^^^^^^^^^^^^^^^^^^^^^^^^^^^^^^^^^^^^^^
  File "C:\python_field\MCF\mcf_riot_api.py", line 206, in <listcomp>
    ids = [int(str(ids.get('class')).split('-')[1]) for ids in game[0:5]]
               ~~~~~~~~~~~~~~~~~~~~~~~~~~~~~~~~^^^
IndexError: list index out of range
2023-11-21 19:32:08,262 ERROR cannot access local variable 'ids' where it is not associated with a value
Traceback (most recent call last):
  File "C:\python_field\MCF\mcf_riot_api.py", line 87, in wrapper
    result = func(*args, **kwargs)
             ^^^^^^^^^^^^^^^^^^^^^
  File "C:\python_field\MCF\mcf_riot_api.py", line 206, in get_poro_games
    print(str(ids.get('class')).split('-'))
              ^^^
UnboundLocalError: cannot access local variable 'ids' where it is not associated with a value
2023-11-21 19:32:39,848 ERROR list index out of range
Traceback (most recent call last):
  File "C:\python_field\MCF\mcf_riot_api.py", line 87, in wrapper
    result = func(*args, **kwargs)
             ^^^^^^^^^^^^^^^^^^^^^
  File "C:\python_field\MCF\mcf_riot_api.py", line 208, in get_poro_games
    ids = [int(str(ids.get('class')).split('-')[1]) for ids in game[0:5]]
          ^^^^^^^^^^^^^^^^^^^^^^^^^^^^^^^^^^^^^^^^^^^^^^^^^^^^^^^^^^^^^^^
  File "C:\python_field\MCF\mcf_riot_api.py", line 208, in <listcomp>
    ids = [int(str(ids.get('class')).split('-')[1]) for ids in game[0:5]]
               ~~~~~~~~~~~~~~~~~~~~~~~~~~~~~~~~^^^
IndexError: list index out of range
2023-11-21 19:33:26,887 ERROR list index out of range
Traceback (most recent call last):
  File "C:\python_field\MCF\mcf_riot_api.py", line 87, in wrapper
    result = func(*args, **kwargs)
             ^^^^^^^^^^^^^^^^^^^^^
  File "C:\python_field\MCF\mcf_riot_api.py", line 208, in get_poro_games
    ids = [int(str(id.get('class')).split('-')[1]) for id in game[0:5]]
          ^^^^^^^^^^^^^^^^^^^^^^^^^^^^^^^^^^^^^^^^^^^^^^^^^^^^^^^^^^^^^
  File "C:\python_field\MCF\mcf_riot_api.py", line 208, in <listcomp>
    ids = [int(str(id.get('class')).split('-')[1]) for id in game[0:5]]
               ~~~~~~~~~~~~~~~~~~~~~~~~~~~~~~~^^^
IndexError: list index out of range
2023-11-21 19:34:26,533 ERROR list index out of range
Traceback (most recent call last):
  File "C:\python_field\MCF\mcf_riot_api.py", line 87, in wrapper
    result = func(*args, **kwargs)
             ^^^^^^^^^^^^^^^^^^^^^
  File "C:\python_field\MCF\mcf_riot_api.py", line 208, in get_poro_games
    ids = [int(str(id.get('class')).split('-')[1]) for id in game[0:5]]
          ^^^^^^^^^^^^^^^^^^^^^^^^^^^^^^^^^^^^^^^^^^^^^^^^^^^^^^^^^^^^^
  File "C:\python_field\MCF\mcf_riot_api.py", line 208, in <listcomp>
    ids = [int(str(id.get('class')).split('-')[1]) for id in game[0:5]]
               ~~~~~~~~~~~~~~~~~~~~~~~~~~~~~~~^^^
IndexError: list index out of range
2023-11-21 19:34:49,063 ERROR list index out of range
Traceback (most recent call last):
  File "C:\python_field\MCF\mcf_riot_api.py", line 87, in wrapper
    result = func(*args, **kwargs)
             ^^^^^^^^^^^^^^^^^^^^^
  File "C:\python_field\MCF\mcf_riot_api.py", line 211, in get_poro_games
    ids = [int(str(id.get('class')).split('-')[1]) for id in game[0:5]]
          ^^^^^^^^^^^^^^^^^^^^^^^^^^^^^^^^^^^^^^^^^^^^^^^^^^^^^^^^^^^^^
  File "C:\python_field\MCF\mcf_riot_api.py", line 211, in <listcomp>
    ids = [int(str(id.get('class')).split('-')[1]) for id in game[0:5]]
               ~~~~~~~~~~~~~~~~~~~~~~~~~~~~~~~^^^
IndexError: list index out of range
2023-11-21 19:35:06,259 ERROR list index out of range
Traceback (most recent call last):
  File "C:\python_field\MCF\mcf_riot_api.py", line 87, in wrapper
    result = func(*args, **kwargs)
             ^^^^^^^^^^^^^^^^^^^^^
  File "C:\python_field\MCF\mcf_riot_api.py", line 212, in get_poro_games
    ids = [int(str(id.get('class')).split('-')[1]) for id in game[0:5]]
          ^^^^^^^^^^^^^^^^^^^^^^^^^^^^^^^^^^^^^^^^^^^^^^^^^^^^^^^^^^^^^
  File "C:\python_field\MCF\mcf_riot_api.py", line 212, in <listcomp>
    ids = [int(str(id.get('class')).split('-')[1]) for id in game[0:5]]
               ~~~~~~~~~~~~~~~~~~~~~~~~~~~~~~~^^^
IndexError: list index out of range
2023-11-21 19:35:52,091 ERROR list index out of range
Traceback (most recent call last):
  File "C:\python_field\MCF\mcf_riot_api.py", line 87, in wrapper
    result = func(*args, **kwargs)
             ^^^^^^^^^^^^^^^^^^^^^
  File "C:\python_field\MCF\mcf_riot_api.py", line 213, in get_poro_games
    ids = [int(str(id.get('class')).split('-')[1]) for id in game[0:5]]
          ^^^^^^^^^^^^^^^^^^^^^^^^^^^^^^^^^^^^^^^^^^^^^^^^^^^^^^^^^^^^^
  File "C:\python_field\MCF\mcf_riot_api.py", line 213, in <listcomp>
    ids = [int(str(id.get('class')).split('-')[1]) for id in game[0:5]]
               ~~~~~~~~~~~~~~~~~~~~~~~~~~~~~~~^^^
IndexError: list index out of range
2023-11-21 19:36:29,706 ERROR list index out of range
Traceback (most recent call last):
  File "C:\python_field\MCF\mcf_riot_api.py", line 87, in wrapper
    result = func(*args, **kwargs)
             ^^^^^^^^^^^^^^^^^^^^^
  File "C:\python_field\MCF\mcf_riot_api.py", line 213, in get_poro_games
    ids = [int(str(id.get('class')).split('-')[1]) for id in game[0:5]]
          ^^^^^^^^^^^^^^^^^^^^^^^^^^^^^^^^^^^^^^^^^^^^^^^^^^^^^^^^^^^^^
  File "C:\python_field\MCF\mcf_riot_api.py", line 213, in <listcomp>
    ids = [int(str(id.get('class')).split('-')[1]) for id in game[0:5]]
               ~~~~~~~~~~~~~~~~~~~~~~~~~~~~~~~^^^
IndexError: list index out of range
2023-11-21 19:37:01,801 ERROR list index out of range
Traceback (most recent call last):
  File "C:\python_field\MCF\mcf_riot_api.py", line 87, in wrapper
    result = func(*args, **kwargs)
             ^^^^^^^^^^^^^^^^^^^^^
  File "C:\python_field\MCF\mcf_riot_api.py", line 213, in get_poro_games
    ids = [int(str(id.get('class')).split('-')[1]) for id in game[0:5]]
          ^^^^^^^^^^^^^^^^^^^^^^^^^^^^^^^^^^^^^^^^^^^^^^^^^^^^^^^^^^^^^
  File "C:\python_field\MCF\mcf_riot_api.py", line 213, in <listcomp>
    ids = [int(str(id.get('class')).split('-')[1]) for id in game[0:5]]
               ~~~~~~~~~~~~~~~~~~~~~~~~~~~~~~~^^^
IndexError: list index out of range
2023-11-21 19:37:43,173 ERROR cannot access local variable 'ids' where it is not associated with a value
Traceback (most recent call last):
  File "C:\python_field\MCF\mcf_riot_api.py", line 87, in wrapper
    result = func(*args, **kwargs)
             ^^^^^^^^^^^^^^^^^^^^^
  File "C:\python_field\MCF\mcf_riot_api.py", line 217, in get_poro_games
    converted_ids = [ALL_CHAMPIONS_IDs.get(i) for i in ids]
                                                       ^^^
UnboundLocalError: cannot access local variable 'ids' where it is not associated with a value
2023-11-21 19:38:01,796 ERROR cannot access local variable 'ids' where it is not associated with a value
Traceback (most recent call last):
  File "C:\python_field\MCF\mcf_riot_api.py", line 87, in wrapper
    result = func(*args, **kwargs)
             ^^^^^^^^^^^^^^^^^^^^^
  File "C:\python_field\MCF\mcf_riot_api.py", line 217, in get_poro_games
    converted_ids = [ALL_CHAMPIONS_IDs.get(i) for i in ids]
                                                       ^^^
UnboundLocalError: cannot access local variable 'ids' where it is not associated with a value
2023-11-21 19:39:16,643 ERROR cannot access local variable 'ids' where it is not associated with a value
Traceback (most recent call last):
  File "C:\python_field\MCF\mcf_riot_api.py", line 87, in wrapper
    result = func(*args, **kwargs)
             ^^^^^^^^^^^^^^^^^^^^^
  File "C:\python_field\MCF\mcf_riot_api.py", line 217, in get_poro_games
    converted_ids = [ALL_CHAMPIONS_IDs.get(i) for i in ids]
                                                       ^^^
UnboundLocalError: cannot access local variable 'ids' where it is not associated with a value
2023-11-21 19:40:13,740 ERROR cannot access local variable 'ids' where it is not associated with a value
Traceback (most recent call last):
  File "C:\python_field\MCF\mcf_riot_api.py", line 87, in wrapper
    result = func(*args, **kwargs)
             ^^^^^^^^^^^^^^^^^^^^^
  File "C:\python_field\MCF\mcf_riot_api.py", line 218, in get_poro_games
    converted_ids = [ALL_CHAMPIONS_IDs.get(i) for i in ids]
                                                       ^^^
UnboundLocalError: cannot access local variable 'ids' where it is not associated with a value
2023-11-21 19:43:16,538 ERROR 'builtin_function_or_method' object has no attribute 'get'
Traceback (most recent call last):
  File "C:\python_field\MCF\mcf_riot_api.py", line 87, in wrapper
    result = func(*args, **kwargs)
             ^^^^^^^^^^^^^^^^^^^^^
  File "C:\python_field\MCF\mcf_riot_api.py", line 209, in get_poro_games
    id_ = int(str(id.get('class')).split('-'))
                  ^^^^^^
AttributeError: 'builtin_function_or_method' object has no attribute 'get'
2023-11-21 19:43:38,643 ERROR int() argument must be a string, a bytes-like object or a real number, not 'list'
Traceback (most recent call last):
  File "C:\python_field\MCF\mcf_riot_api.py", line 87, in wrapper
    result = func(*args, **kwargs)
             ^^^^^^^^^^^^^^^^^^^^^
  File "C:\python_field\MCF\mcf_riot_api.py", line 209, in get_poro_games
    id_ = int(str(info_stroke.get('class')).split('-'))
          ^^^^^^^^^^^^^^^^^^^^^^^^^^^^^^^^^^^^^^^^^^^^^
TypeError: int() argument must be a string, a bytes-like object or a real number, not 'list'
2023-11-21 19:44:37,288 ERROR list index out of range
Traceback (most recent call last):
  File "C:\python_field\MCF\mcf_riot_api.py", line 87, in wrapper
    result = func(*args, **kwargs)
             ^^^^^^^^^^^^^^^^^^^^^
  File "C:\python_field\MCF\mcf_riot_api.py", line 211, in get_poro_games
    ids.append(int(id_[1]))
                   ~~~^^^
IndexError: list index out of range
2023-11-21 19:44:55,553 ERROR list index out of range
Traceback (most recent call last):
  File "C:\python_field\MCF\mcf_riot_api.py", line 87, in wrapper
    result = func(*args, **kwargs)
             ^^^^^^^^^^^^^^^^^^^^^
  File "C:\python_field\MCF\mcf_riot_api.py", line 212, in get_poro_games
    ids.append(int(id_[1]))
                   ~~~^^^
IndexError: list index out of range
2023-11-21 19:45:20,140 ERROR 'list' object has no attribute 'split'
Traceback (most recent call last):
  File "C:\python_field\MCF\mcf_riot_api.py", line 87, in wrapper
    result = func(*args, **kwargs)
             ^^^^^^^^^^^^^^^^^^^^^
  File "C:\python_field\MCF\mcf_riot_api.py", line 209, in get_poro_games
    id_ = info_stroke.get('class').split('-')
          ^^^^^^^^^^^^^^^^^^^^^^^^^^^^^^
AttributeError: 'list' object has no attribute 'split'
2023-11-21 19:45:43,845 ERROR 'list' object has no attribute 'split'
Traceback (most recent call last):
  File "C:\python_field\MCF\mcf_riot_api.py", line 87, in wrapper
    result = func(*args, **kwargs)
             ^^^^^^^^^^^^^^^^^^^^^
  File "C:\python_field\MCF\mcf_riot_api.py", line 210, in get_poro_games
    id_ = info_stroke.get('class').split('-')
          ^^^^^^^^^^^^^^^^^^^^^^^^^^^^^^
AttributeError: 'list' object has no attribute 'split'
2023-11-21 19:47:47,333 ERROR list index out of range
Traceback (most recent call last):
  File "C:\python_field\MCF\mcf_riot_api.py", line 87, in wrapper
    result = func(*args, **kwargs)
             ^^^^^^^^^^^^^^^^^^^^^
  File "C:\python_field\MCF\mcf_riot_api.py", line 210, in get_poro_games
    id_ = info_stroke.get('class')[0]
          ~~~~~~~~~~~~~~~~~~~~~~~~^^^
IndexError: list index out of range
2023-11-26 00:51:18,476 ERROR ResultSet object has no attribute 'text'. You're probably treating a list of elements like a single element. Did you call find_all() when you meant to call find()?
Traceback (most recent call last):
  File "C:\python_field\MCF\mcf_riot_api.py", line 87, in wrapper
    result = func(*args, **kwargs)
             ^^^^^^^^^^^^^^^^^^^^^
  File "C:\python_field\MCF\mcf_riot_api.py", line 195, in get_poro_games
    'nicknames': [team.find_all('div', class_='name').text.strip() for i, team in enumerate(soup) if i % 2 == 0],
                 ^^^^^^^^^^^^^^^^^^^^^^^^^^^^^^^^^^^^^^^^^^^^^^^^^^^^^^^^^^^^^^^^^^^^^^^^^^^^^^^^^^^^^^^^^^^^^^^
  File "C:\python_field\MCF\mcf_riot_api.py", line 195, in <listcomp>
    'nicknames': [team.find_all('div', class_='name').text.strip() for i, team in enumerate(soup) if i % 2 == 0],
                  ^^^^^^^^^^^^^^^^^^^^^^^^^^^^^^^^^^^^^^^^
  File "C:\python_field\MCF\.mcfenv\Lib\site-packages\bs4\element.py", line 2289, in __getattr__
    raise AttributeError(
AttributeError: ResultSet object has no attribute 'text'. You're probably treating a list of elements like a single element. Did you call find_all() when you meant to call find()?
2023-11-26 00:52:18,467 ERROR ResultSet object has no attribute 'text'. You're probably treating a list of elements like a single element. Did you call find_all() when you meant to call find()?
Traceback (most recent call last):
  File "C:\python_field\MCF\mcf_riot_api.py", line 87, in wrapper
    result = func(*args, **kwargs)
             ^^^^^^^^^^^^^^^^^^^^^
  File "C:\python_field\MCF\mcf_riot_api.py", line 195, in get_poro_games
    'nicknames': [team.find_all_next('div', class_='name').text.strip() for i, team in enumerate(soup) if i % 2 == 0],
                 ^^^^^^^^^^^^^^^^^^^^^^^^^^^^^^^^^^^^^^^^^^^^^^^^^^^^^^^^^^^^^^^^^^^^^^^^^^^^^^^^^^^^^^^^^^^^^^^^^^^^
  File "C:\python_field\MCF\mcf_riot_api.py", line 195, in <listcomp>
    'nicknames': [team.find_all_next('div', class_='name').text.strip() for i, team in enumerate(soup) if i % 2 == 0],
                  ^^^^^^^^^^^^^^^^^^^^^^^^^^^^^^^^^^^^^^^^^^^^^
  File "C:\python_field\MCF\.mcfenv\Lib\site-packages\bs4\element.py", line 2289, in __getattr__
    raise AttributeError(
AttributeError: ResultSet object has no attribute 'text'. You're probably treating a list of elements like a single element. Did you call find_all() when you meant to call find()?
2023-11-26 00:52:44,145 ERROR ResultSet object has no attribute 'find_all'. You're probably treating a list of elements like a single element. Did you call find_all() when you meant to call find()?
Traceback (most recent call last):
  File "C:\python_field\MCF\mcf_riot_api.py", line 87, in wrapper
    result = func(*args, **kwargs)
             ^^^^^^^^^^^^^^^^^^^^^
  File "C:\python_field\MCF\mcf_riot_api.py", line 200, in get_poro_games
    print(soup.find_all('div', class_='name'))
          ^^^^^^^^^^^^^
  File "C:\python_field\MCF\.mcfenv\Lib\site-packages\bs4\element.py", line 2289, in __getattr__
    raise AttributeError(
AttributeError: ResultSet object has no attribute 'find_all'. You're probably treating a list of elements like a single element. Did you call find_all() when you meant to call find()?
2023-11-26 00:54:30,529 ERROR ResultSet object has no attribute 'text'. You're probably treating a list of elements like a single element. Did you call find_all() when you meant to call find()?
Traceback (most recent call last):
  File "C:\python_field\MCF\mcf_riot_api.py", line 87, in wrapper
    result = func(*args, **kwargs)
             ^^^^^^^^^^^^^^^^^^^^^
  File "C:\python_field\MCF\mcf_riot_api.py", line 201, in get_poro_games
    print(i.find_all('div', class_='name').text.strip())
          ^^^^^^^^^^^^^^^^^^^^^^^^^^^^^^^^^^^^^
  File "C:\python_field\MCF\.mcfenv\Lib\site-packages\bs4\element.py", line 2289, in __getattr__
    raise AttributeError(
AttributeError: ResultSet object has no attribute 'text'. You're probably treating a list of elements like a single element. Did you call find_all() when you meant to call find()?
2023-11-26 00:55:13,157 ERROR 'NavigableString' object has no attribute 'find_all'
Traceback (most recent call last):
  File "C:\python_field\MCF\mcf_riot_api.py", line 87, in wrapper
    result = func(*args, **kwargs)
             ^^^^^^^^^^^^^^^^^^^^^
  File "C:\python_field\MCF\mcf_riot_api.py", line 201, in get_poro_games
    print([ch.find_all('div', class_='name').text.strip() for ch in i])
          ^^^^^^^^^^^^^^^^^^^^^^^^^^^^^^^^^^^^^^^^^^^^^^^^^^^^^^^^^^^^
  File "C:\python_field\MCF\mcf_riot_api.py", line 201, in <listcomp>
    print([ch.find_all('div', class_='name').text.strip() for ch in i])
           ^^^^^^^^^^^
  File "C:\python_field\MCF\.mcfenv\Lib\site-packages\bs4\element.py", line 965, in __getattr__
    raise AttributeError(
AttributeError: 'NavigableString' object has no attribute 'find_all'
2023-11-26 01:04:14,148 ERROR cannot access free variable 'r' where it is not associated with a value in enclosing scope
Traceback (most recent call last):
  File "C:\python_field\MCF\mcf_riot_api.py", line 87, in wrapper
    result = func(*args, **kwargs)
             ^^^^^^^^^^^^^^^^^^^^^
  File "C:\python_field\MCF\mcf_riot_api.py", line 203, in get_poro_games
    nicknames_regions = [f"{n}:{r.split('/')[2].upper()}".join('_') for n in nicknames]
                        ^^^^^^^^^^^^^^^^^^^^^^^^^^^^^^^^^^^^^^^^^^^^^^^^^^^^^^^^^^^^^^^
  File "C:\python_field\MCF\mcf_riot_api.py", line 203, in <listcomp>
    nicknames_regions = [f"{n}:{r.split('/')[2].upper()}".join('_') for n in nicknames]
                                ^
NameError: cannot access free variable 'r' where it is not associated with a value in enclosing scope
2023-11-28 12:48:18,140 ERROR Task exception was never retrieved
future: <Task finished name='Task-15' coro=<parse_games.<locals>.parsing() done, defined at C:\python_field\MCF\modules\scripts\async_featured_games.py:23> exception=KeyError('gameList')>
Traceback (most recent call last):
  File "C:\python_field\MCF\modules\scripts\async_featured_games.py", line 31, in parsing
    gameList = data['gameList']
               ~~~~^^^^^^^^^^^^
KeyError: 'gameList'
2023-11-28 12:48:18,142 ERROR Task exception was never retrieved
future: <Task finished name='Task-16' coro=<parse_games.<locals>.parsing() done, defined at C:\python_field\MCF\modules\scripts\async_featured_games.py:23> exception=KeyError('gameList')>
Traceback (most recent call last):
  File "C:\python_field\MCF\modules\scripts\async_featured_games.py", line 31, in parsing
    gameList = data['gameList']
               ~~~~^^^^^^^^^^^^
KeyError: 'gameList'
2023-11-28 12:48:18,143 ERROR Task exception was never retrieved
future: <Task finished name='Task-17' coro=<parse_games.<locals>.parsing() done, defined at C:\python_field\MCF\modules\scripts\async_featured_games.py:23> exception=KeyError('gameList')>
Traceback (most recent call last):
  File "C:\python_field\MCF\modules\scripts\async_featured_games.py", line 31, in parsing
    gameList = data['gameList']
               ~~~~^^^^^^^^^^^^
KeyError: 'gameList'
2023-11-29 18:45:19,165 ERROR Task exception was never retrieved
future: <Task finished name='Task-14' coro=<parse_games.<locals>.parsing() done, defined at C:\python_field\MCF\modules\scripts\async_featured_games.py:23> exception=KeyError('gameList')>
Traceback (most recent call last):
  File "C:\python_field\MCF\modules\scripts\async_featured_games.py", line 31, in parsing
    gameList = data['gameList']
               ~~~~^^^^^^^^^^^^
KeyError: 'gameList'
2023-11-29 18:45:19,167 ERROR Task exception was never retrieved
future: <Task finished name='Task-15' coro=<parse_games.<locals>.parsing() done, defined at C:\python_field\MCF\modules\scripts\async_featured_games.py:23> exception=KeyError('gameList')>
Traceback (most recent call last):
  File "C:\python_field\MCF\modules\scripts\async_featured_games.py", line 31, in parsing
    gameList = data['gameList']
               ~~~~^^^^^^^^^^^^
KeyError: 'gameList'
2023-11-29 18:45:19,168 ERROR Task exception was never retrieved
future: <Task finished name='Task-16' coro=<parse_games.<locals>.parsing() done, defined at C:\python_field\MCF\modules\scripts\async_featured_games.py:23> exception=KeyError('gameList')>
Traceback (most recent call last):
  File "C:\python_field\MCF\modules\scripts\async_featured_games.py", line 31, in parsing
    gameList = data['gameList']
               ~~~~^^^^^^^^^^^^
KeyError: 'gameList'
2023-11-29 18:45:19,168 ERROR Task exception was never retrieved
future: <Task finished name='Task-17' coro=<parse_games.<locals>.parsing() done, defined at C:\python_field\MCF\modules\scripts\async_featured_games.py:23> exception=KeyError('gameList')>
Traceback (most recent call last):
  File "C:\python_field\MCF\modules\scripts\async_featured_games.py", line 31, in parsing
    gameList = data['gameList']
               ~~~~^^^^^^^^^^^^
KeyError: 'gameList'
2023-12-03 22:08:14,870 ERROR Task exception was never retrieved
future: <Task finished name='Task-17' coro=<parse_games.<locals>.parsing() done, defined at C:\python_field\MCF\modules\scripts\async_poro_games.py:26> exception=AttributeError("type object 'PoroAPI' has no attribute '__headers_timeout'")>
Traceback (most recent call last):
  File "C:\python_field\MCF\modules\scripts\async_poro_games.py", line 31, in parsing
    **PoroAPI.__headers_timeout) as response:
      ^^^^^^^^^^^^^^^^^^^^^^^^^
AttributeError: type object 'PoroAPI' has no attribute '__headers_timeout'
2023-12-03 22:08:14,873 ERROR Task exception was never retrieved
future: <Task finished name='Task-16' coro=<parse_games.<locals>.parsing() done, defined at C:\python_field\MCF\modules\scripts\async_poro_games.py:26> exception=AttributeError("type object 'PoroAPI' has no attribute '__headers_timeout'")>
Traceback (most recent call last):
  File "C:\python_field\MCF\modules\scripts\async_poro_games.py", line 31, in parsing
    **PoroAPI.__headers_timeout) as response:
      ^^^^^^^^^^^^^^^^^^^^^^^^^
AttributeError: type object 'PoroAPI' has no attribute '__headers_timeout'
2023-12-03 22:08:14,874 ERROR Task exception was never retrieved
future: <Task finished name='Task-15' coro=<parse_games.<locals>.parsing() done, defined at C:\python_field\MCF\modules\scripts\async_poro_games.py:26> exception=AttributeError("type object 'PoroAPI' has no attribute '__headers_timeout'")>
Traceback (most recent call last):
  File "C:\python_field\MCF\modules\scripts\async_poro_games.py", line 31, in parsing
    **PoroAPI.__headers_timeout) as response:
      ^^^^^^^^^^^^^^^^^^^^^^^^^
AttributeError: type object 'PoroAPI' has no attribute '__headers_timeout'
2023-12-03 22:08:14,875 ERROR Task exception was never retrieved
future: <Task finished name='Task-14' coro=<parse_games.<locals>.parsing() done, defined at C:\python_field\MCF\modules\scripts\async_poro_games.py:26> exception=AttributeError("type object 'PoroAPI' has no attribute '__headers_timeout'")>
Traceback (most recent call last):
  File "C:\python_field\MCF\modules\scripts\async_poro_games.py", line 31, in parsing
    **PoroAPI.__headers_timeout) as response:
      ^^^^^^^^^^^^^^^^^^^^^^^^^
AttributeError: type object 'PoroAPI' has no attribute '__headers_timeout'
2023-12-03 22:08:14,876 ERROR Task exception was never retrieved
future: <Task finished name='Task-13' coro=<parse_games.<locals>.parsing() done, defined at C:\python_field\MCF\modules\scripts\async_poro_games.py:26> exception=AttributeError("type object 'PoroAPI' has no attribute '__headers_timeout'")>
Traceback (most recent call last):
  File "C:\python_field\MCF\modules\scripts\async_poro_games.py", line 31, in parsing
    **PoroAPI.__headers_timeout) as response:
      ^^^^^^^^^^^^^^^^^^^^^^^^^
AttributeError: type object 'PoroAPI' has no attribute '__headers_timeout'
2023-12-03 22:08:14,878 ERROR Task exception was never retrieved
future: <Task finished name='Task-12' coro=<parse_games.<locals>.parsing() done, defined at C:\python_field\MCF\modules\scripts\async_poro_games.py:26> exception=AttributeError("type object 'PoroAPI' has no attribute '__headers_timeout'")>
Traceback (most recent call last):
  File "C:\python_field\MCF\modules\scripts\async_poro_games.py", line 31, in parsing
    **PoroAPI.__headers_timeout) as response:
      ^^^^^^^^^^^^^^^^^^^^^^^^^
AttributeError: type object 'PoroAPI' has no attribute '__headers_timeout'
2023-12-03 22:08:14,879 ERROR Task exception was never retrieved
future: <Task finished name='Task-11' coro=<parse_games.<locals>.parsing() done, defined at C:\python_field\MCF\modules\scripts\async_poro_games.py:26> exception=AttributeError("type object 'PoroAPI' has no attribute '__headers_timeout'")>
Traceback (most recent call last):
  File "C:\python_field\MCF\modules\scripts\async_poro_games.py", line 31, in parsing
    **PoroAPI.__headers_timeout) as response:
      ^^^^^^^^^^^^^^^^^^^^^^^^^
AttributeError: type object 'PoroAPI' has no attribute '__headers_timeout'
2023-12-03 22:08:14,881 ERROR Task exception was never retrieved
future: <Task finished name='Task-10' coro=<parse_games.<locals>.parsing() done, defined at C:\python_field\MCF\modules\scripts\async_poro_games.py:26> exception=AttributeError("type object 'PoroAPI' has no attribute '__headers_timeout'")>
Traceback (most recent call last):
  File "C:\python_field\MCF\modules\scripts\async_poro_games.py", line 31, in parsing
    **PoroAPI.__headers_timeout) as response:
      ^^^^^^^^^^^^^^^^^^^^^^^^^
AttributeError: type object 'PoroAPI' has no attribute '__headers_timeout'
2023-12-03 22:08:14,882 ERROR Task exception was never retrieved
future: <Task finished name='Task-9' coro=<parse_games.<locals>.parsing() done, defined at C:\python_field\MCF\modules\scripts\async_poro_games.py:26> exception=AttributeError("type object 'PoroAPI' has no attribute '__headers_timeout'")>
Traceback (most recent call last):
  File "C:\python_field\MCF\modules\scripts\async_poro_games.py", line 31, in parsing
    **PoroAPI.__headers_timeout) as response:
      ^^^^^^^^^^^^^^^^^^^^^^^^^
AttributeError: type object 'PoroAPI' has no attribute '__headers_timeout'
2023-12-03 22:08:14,883 ERROR Task exception was never retrieved
future: <Task finished name='Task-8' coro=<parse_games.<locals>.parsing() done, defined at C:\python_field\MCF\modules\scripts\async_poro_games.py:26> exception=AttributeError("type object 'PoroAPI' has no attribute '__headers_timeout'")>
Traceback (most recent call last):
  File "C:\python_field\MCF\modules\scripts\async_poro_games.py", line 31, in parsing
    **PoroAPI.__headers_timeout) as response:
      ^^^^^^^^^^^^^^^^^^^^^^^^^
AttributeError: type object 'PoroAPI' has no attribute '__headers_timeout'
2023-12-03 22:08:14,885 ERROR Task exception was never retrieved
future: <Task finished name='Task-7' coro=<parse_games.<locals>.parsing() done, defined at C:\python_field\MCF\modules\scripts\async_poro_games.py:26> exception=AttributeError("type object 'PoroAPI' has no attribute '__headers_timeout'")>
Traceback (most recent call last):
  File "C:\python_field\MCF\modules\scripts\async_poro_games.py", line 31, in parsing
    **PoroAPI.__headers_timeout) as response:
      ^^^^^^^^^^^^^^^^^^^^^^^^^
AttributeError: type object 'PoroAPI' has no attribute '__headers_timeout'
2023-12-03 22:08:14,886 ERROR Task exception was never retrieved
future: <Task finished name='Task-6' coro=<parse_games.<locals>.parsing() done, defined at C:\python_field\MCF\modules\scripts\async_poro_games.py:26> exception=AttributeError("type object 'PoroAPI' has no attribute '__headers_timeout'")>
Traceback (most recent call last):
  File "C:\python_field\MCF\modules\scripts\async_poro_games.py", line 31, in parsing
    **PoroAPI.__headers_timeout) as response:
      ^^^^^^^^^^^^^^^^^^^^^^^^^
AttributeError: type object 'PoroAPI' has no attribute '__headers_timeout'
2023-12-03 22:08:14,888 ERROR Task exception was never retrieved
future: <Task finished name='Task-5' coro=<parse_games.<locals>.parsing() done, defined at C:\python_field\MCF\modules\scripts\async_poro_games.py:26> exception=AttributeError("type object 'PoroAPI' has no attribute '__headers_timeout'")>
Traceback (most recent call last):
  File "C:\python_field\MCF\modules\scripts\async_poro_games.py", line 31, in parsing
    **PoroAPI.__headers_timeout) as response:
      ^^^^^^^^^^^^^^^^^^^^^^^^^
AttributeError: type object 'PoroAPI' has no attribute '__headers_timeout'
2023-12-03 22:08:14,890 ERROR Task exception was never retrieved
future: <Task finished name='Task-4' coro=<parse_games.<locals>.parsing() done, defined at C:\python_field\MCF\modules\scripts\async_poro_games.py:26> exception=AttributeError("type object 'PoroAPI' has no attribute '__headers_timeout'")>
Traceback (most recent call last):
  File "C:\python_field\MCF\modules\scripts\async_poro_games.py", line 31, in parsing
    **PoroAPI.__headers_timeout) as response:
      ^^^^^^^^^^^^^^^^^^^^^^^^^
AttributeError: type object 'PoroAPI' has no attribute '__headers_timeout'
2023-12-03 22:08:14,891 ERROR Task exception was never retrieved
future: <Task finished name='Task-3' coro=<parse_games.<locals>.parsing() done, defined at C:\python_field\MCF\modules\scripts\async_poro_games.py:26> exception=AttributeError("type object 'PoroAPI' has no attribute '__headers_timeout'")>
Traceback (most recent call last):
  File "C:\python_field\MCF\modules\scripts\async_poro_games.py", line 31, in parsing
    **PoroAPI.__headers_timeout) as response:
      ^^^^^^^^^^^^^^^^^^^^^^^^^
AttributeError: type object 'PoroAPI' has no attribute '__headers_timeout'
2023-12-03 22:10:11,543 ERROR Task exception was never retrieved
future: <Task finished name='Task-13' coro=<parse_games.<locals>.parsing() done, defined at C:\python_field\MCF\modules\scripts\async_poro_games.py:26> exception=ContentTypeError(RequestInfo(url=URL('https://porofessor.gg/current-games/vn/garenqueue-450'), method='GET', headers=<CIMultiDictProxy('Host': 'porofessor.gg', 'User-Agent': 'Mozilla/5.0 (Windows NT 10.0; Win64; x64) AppleWebKit/537.36 (KHTML, like Gecko) Chrome/111.0.0.0 Safari/537.36', 'Accept': '*/*', 'Accept-Encoding': 'gzip, deflate')>, real_url=URL('https://porofessor.gg/current-games/vn/garenqueue-450')), (), message='Attempt to decode JSON with unexpected mimetype: text/html; charset=utf-8', headers=<CIMultiDictProxy('Date': 'Sun, 03 Dec 2023 19:10:02 GMT', 'x-frame-options': 'SAMEORIGIN', 'fid': 'www-6', 'cv': 'CV-PcTTAoJ3zeAh', 'Vary': 'Accept-Encoding', 'Content-Encoding': 'gzip', 'Content-Length': '4564', 'Content-Type': 'text/html; charset=UTF-8')>)>
Traceback (most recent call last):
  File "C:\python_field\MCF\modules\scripts\async_poro_games.py", line 35, in parsing
    result = await response.json()
             ^^^^^^^^^^^^^^^^^^^^^
  File "C:\python_field\MCF\.mcfenv\Lib\site-packages\aiohttp\client_reqrep.py", line 1104, in json
    raise ContentTypeError(
aiohttp.client_exceptions.ContentTypeError: 0, message='Attempt to decode JSON with unexpected mimetype: text/html; charset=utf-8', url=URL('https://porofessor.gg/current-games/vn/garenqueue-450')
2023-12-03 22:10:11,545 ERROR Task exception was never retrieved
future: <Task finished name='Task-10' coro=<parse_games.<locals>.parsing() done, defined at C:\python_field\MCF\modules\scripts\async_poro_games.py:26> exception=ContentTypeError(RequestInfo(url=URL('https://porofessor.gg/current-games/euw/garenqueue-450'), method='GET', headers=<CIMultiDictProxy('Host': 'porofessor.gg', 'User-Agent': 'Mozilla/5.0 (Windows NT 10.0; Win64; x64) AppleWebKit/537.36 (KHTML, like Gecko) Chrome/111.0.0.0 Safari/537.36', 'Accept': '*/*', 'Accept-Encoding': 'gzip, deflate')>, real_url=URL('https://porofessor.gg/current-games/euw/garenqueue-450')), (), message='Attempt to decode JSON with unexpected mimetype: text/html; charset=utf-8', headers=<CIMultiDictProxy('Date': 'Sun, 03 Dec 2023 19:10:02 GMT', 'x-frame-options': 'SAMEORIGIN', 'fid': 'www-18', 'cv': 'CV-fqlvlslPVIM1', 'Vary': 'Accept-Encoding', 'Content-Encoding': 'gzip', 'Content-Length': '4563', 'Content-Type': 'text/html; charset=UTF-8')>)>
Traceback (most recent call last):
  File "C:\python_field\MCF\modules\scripts\async_poro_games.py", line 35, in parsing
    result = await response.json()
             ^^^^^^^^^^^^^^^^^^^^^
  File "C:\python_field\MCF\.mcfenv\Lib\site-packages\aiohttp\client_reqrep.py", line 1104, in json
    raise ContentTypeError(
aiohttp.client_exceptions.ContentTypeError: 0, message='Attempt to decode JSON with unexpected mimetype: text/html; charset=utf-8', url=URL('https://porofessor.gg/current-games/euw/garenqueue-450')
2023-12-03 22:10:11,547 ERROR Task exception was never retrieved
future: <Task finished name='Task-7' coro=<parse_games.<locals>.parsing() done, defined at C:\python_field\MCF\modules\scripts\async_poro_games.py:26> exception=ContentTypeError(RequestInfo(url=URL('https://porofessor.gg/current-games/eune/garenqueue-450'), method='GET', headers=<CIMultiDictProxy('Host': 'porofessor.gg', 'User-Agent': 'Mozilla/5.0 (Windows NT 10.0; Win64; x64) AppleWebKit/537.36 (KHTML, like Gecko) Chrome/111.0.0.0 Safari/537.36', 'Accept': '*/*', 'Accept-Encoding': 'gzip, deflate')>, real_url=URL('https://porofessor.gg/current-games/eune/garenqueue-450')), (), message='Attempt to decode JSON with unexpected mimetype: text/html; charset=utf-8', headers=<CIMultiDictProxy('Date': 'Sun, 03 Dec 2023 19:10:02 GMT', 'x-frame-options': 'SAMEORIGIN', 'fid': 'www-5', 'cv': 'CV-7C8kSqBKaW95', 'Vary': 'Accept-Encoding', 'Content-Encoding': 'gzip', 'Content-Length': '4565', 'Content-Type': 'text/html; charset=UTF-8')>)>
Traceback (most recent call last):
  File "C:\python_field\MCF\modules\scripts\async_poro_games.py", line 35, in parsing
    result = await response.json()
             ^^^^^^^^^^^^^^^^^^^^^
  File "C:\python_field\MCF\.mcfenv\Lib\site-packages\aiohttp\client_reqrep.py", line 1104, in json
    raise ContentTypeError(
aiohttp.client_exceptions.ContentTypeError: 0, message='Attempt to decode JSON with unexpected mimetype: text/html; charset=utf-8', url=URL('https://porofessor.gg/current-games/eune/garenqueue-450')
2023-12-03 22:10:11,549 ERROR Task exception was never retrieved
future: <Task finished name='Task-6' coro=<parse_games.<locals>.parsing() done, defined at C:\python_field\MCF\modules\scripts\async_poro_games.py:26> exception=ContentTypeError(RequestInfo(url=URL('https://porofessor.gg/current-games/oce/garenqueue-450'), method='GET', headers=<CIMultiDictProxy('Host': 'porofessor.gg', 'User-Agent': 'Mozilla/5.0 (Windows NT 10.0; Win64; x64) AppleWebKit/537.36 (KHTML, like Gecko) Chrome/111.0.0.0 Safari/537.36', 'Accept': '*/*', 'Accept-Encoding': 'gzip, deflate')>, real_url=URL('https://porofessor.gg/current-games/oce/garenqueue-450')), (), message='Attempt to decode JSON with unexpected mimetype: text/html; charset=utf-8', headers=<CIMultiDictProxy('Date': 'Sun, 03 Dec 2023 19:10:02 GMT', 'x-frame-options': 'SAMEORIGIN', 'fid': 'www-0', 'cv': 'CV-JldTTDyhRiHq', 'Vary': 'Accept-Encoding', 'Content-Encoding': 'gzip', 'Content-Length': '4563', 'Content-Type': 'text/html; charset=UTF-8')>)>
Traceback (most recent call last):
  File "C:\python_field\MCF\modules\scripts\async_poro_games.py", line 35, in parsing
    result = await response.json()
             ^^^^^^^^^^^^^^^^^^^^^
  File "C:\python_field\MCF\.mcfenv\Lib\site-packages\aiohttp\client_reqrep.py", line 1104, in json
    raise ContentTypeError(
aiohttp.client_exceptions.ContentTypeError: 0, message='Attempt to decode JSON with unexpected mimetype: text/html; charset=utf-8', url=URL('https://porofessor.gg/current-games/oce/garenqueue-450')
2023-12-03 22:10:11,550 ERROR Task exception was never retrieved
future: <Task finished name='Task-3' coro=<parse_games.<locals>.parsing() done, defined at C:\python_field\MCF\modules\scripts\async_poro_games.py:26> exception=ContentTypeError(RequestInfo(url=URL('https://porofessor.gg/current-games/lan/garenqueue-450'), method='GET', headers=<CIMultiDictProxy('Host': 'porofessor.gg', 'User-Agent': 'Mozilla/5.0 (Windows NT 10.0; Win64; x64) AppleWebKit/537.36 (KHTML, like Gecko) Chrome/111.0.0.0 Safari/537.36', 'Accept': '*/*', 'Accept-Encoding': 'gzip, deflate')>, real_url=URL('https://porofessor.gg/current-games/lan/garenqueue-450')), (), message='Attempt to decode JSON with unexpected mimetype: text/html; charset=utf-8', headers=<CIMultiDictProxy('Date': 'Sun, 03 Dec 2023 19:10:02 GMT', 'x-frame-options': 'SAMEORIGIN', 'fid': 'www-20', 'cv': 'CV-QURIgnz4aKOM', 'Vary': 'Accept-Encoding', 'Content-Encoding': 'gzip', 'Content-Length': '4562', 'Content-Type': 'text/html; charset=UTF-8')>)>
Traceback (most recent call last):
  File "C:\python_field\MCF\modules\scripts\async_poro_games.py", line 35, in parsing
    result = await response.json()
             ^^^^^^^^^^^^^^^^^^^^^
  File "C:\python_field\MCF\.mcfenv\Lib\site-packages\aiohttp\client_reqrep.py", line 1104, in json
    raise ContentTypeError(
aiohttp.client_exceptions.ContentTypeError: 0, message='Attempt to decode JSON with unexpected mimetype: text/html; charset=utf-8', url=URL('https://porofessor.gg/current-games/lan/garenqueue-450')
2023-12-03 22:11:31,057 ERROR Task exception was never retrieved
future: <Task finished name='Task-16' coro=<parse_games.<locals>.parsing() done, defined at C:\python_field\MCF\modules\scripts\async_poro_games.py:26> exception=ContentTypeError(RequestInfo(url=URL('https://porofessor.gg/current-games/th/garen/queue-450'), method='GET', headers=<CIMultiDictProxy('Host': 'porofessor.gg', 'User-Agent': 'Mozilla/5.0 (Windows NT 10.0; Win64; x64) AppleWebKit/537.36 (KHTML, like Gecko) Chrome/111.0.0.0 Safari/537.36', 'Accept': '*/*', 'Accept-Encoding': 'gzip, deflate')>, real_url=URL('https://porofessor.gg/current-games/th/garen/queue-450')), (), message='Attempt to decode JSON with unexpected mimetype: text/html; charset=utf-8', headers=<CIMultiDictProxy('Date': 'Sun, 03 Dec 2023 19:10:38 GMT', 'x-frame-options': 'SAMEORIGIN', 'fid': 'www-19', 'cv': 'CV-toRq05VSKxKC', 'Vary': 'Accept-Encoding', 'Content-Encoding': 'gzip', 'Content-Length': '4564', 'Content-Type': 'text/html; charset=UTF-8')>)>
Traceback (most recent call last):
  File "C:\python_field\MCF\modules\scripts\async_poro_games.py", line 35, in parsing
    result = await response.text()
             ^^^^^^^^^^^^^^^^^^^^^
  File "C:\python_field\MCF\.mcfenv\Lib\site-packages\aiohttp\client_reqrep.py", line 1104, in json
    raise ContentTypeError(
aiohttp.client_exceptions.ContentTypeError: 0, message='Attempt to decode JSON with unexpected mimetype: text/html; charset=utf-8', url=URL('https://porofessor.gg/current-games/th/garen/queue-450')
2023-12-03 22:11:31,059 ERROR Task exception was never retrieved
future: <Task finished name='Task-15' coro=<parse_games.<locals>.parsing() done, defined at C:\python_field\MCF\modules\scripts\async_poro_games.py:26> exception=ContentTypeError(RequestInfo(url=URL('https://porofessor.gg/current-games/ph/garen/queue-450'), method='GET', headers=<CIMultiDictProxy('Host': 'porofessor.gg', 'User-Agent': 'Mozilla/5.0 (Windows NT 10.0; Win64; x64) AppleWebKit/537.36 (KHTML, like Gecko) Chrome/111.0.0.0 Safari/537.36', 'Accept': '*/*', 'Accept-Encoding': 'gzip, deflate')>, real_url=URL('https://porofessor.gg/current-games/ph/garen/queue-450')), (), message='Attempt to decode JSON with unexpected mimetype: text/html; charset=utf-8', headers=<CIMultiDictProxy('Date': 'Sun, 03 Dec 2023 19:10:38 GMT', 'x-frame-options': 'SAMEORIGIN', 'fid': 'www-19', 'cv': 'CV-3iCs4Qg7UDcB', 'Vary': 'Accept-Encoding', 'Content-Encoding': 'gzip', 'Content-Length': '4563', 'Content-Type': 'text/html; charset=UTF-8')>)>
Traceback (most recent call last):
  File "C:\python_field\MCF\modules\scripts\async_poro_games.py", line 35, in parsing
    result = await response.text()
             ^^^^^^^^^^^^^^^^^^^^^
  File "C:\python_field\MCF\.mcfenv\Lib\site-packages\aiohttp\client_reqrep.py", line 1104, in json
    raise ContentTypeError(
aiohttp.client_exceptions.ContentTypeError: 0, message='Attempt to decode JSON with unexpected mimetype: text/html; charset=utf-8', url=URL('https://porofessor.gg/current-games/ph/garen/queue-450')
2023-12-03 22:11:31,062 ERROR Task exception was never retrieved
future: <Task finished name='Task-14' coro=<parse_games.<locals>.parsing() done, defined at C:\python_field\MCF\modules\scripts\async_poro_games.py:26> exception=ContentTypeError(RequestInfo(url=URL('https://porofessor.gg/current-games/sg/garen/queue-450'), method='GET', headers=<CIMultiDictProxy('Host': 'porofessor.gg', 'User-Agent': 'Mozilla/5.0 (Windows NT 10.0; Win64; x64) AppleWebKit/537.36 (KHTML, like Gecko) Chrome/111.0.0.0 Safari/537.36', 'Accept': '*/*', 'Accept-Encoding': 'gzip, deflate')>, real_url=URL('https://porofessor.gg/current-games/sg/garen/queue-450')), (), message='Attempt to decode JSON with unexpected mimetype: text/html; charset=utf-8', headers=<CIMultiDictProxy('Date': 'Sun, 03 Dec 2023 19:10:38 GMT', 'x-frame-options': 'SAMEORIGIN', 'fid': 'www-9', 'cv': 'CV-pEbe8na0VwA3', 'Vary': 'Accept-Encoding', 'Content-Encoding': 'gzip', 'Content-Length': '4562', 'Content-Type': 'text/html; charset=UTF-8')>)>
Traceback (most recent call last):
  File "C:\python_field\MCF\modules\scripts\async_poro_games.py", line 35, in parsing
    result = await response.text()
             ^^^^^^^^^^^^^^^^^^^^^
  File "C:\python_field\MCF\.mcfenv\Lib\site-packages\aiohttp\client_reqrep.py", line 1104, in json
    raise ContentTypeError(
aiohttp.client_exceptions.ContentTypeError: 0, message='Attempt to decode JSON with unexpected mimetype: text/html; charset=utf-8', url=URL('https://porofessor.gg/current-games/sg/garen/queue-450')
2023-12-03 22:11:31,064 ERROR Task exception was never retrieved
future: <Task finished name='Task-13' coro=<parse_games.<locals>.parsing() done, defined at C:\python_field\MCF\modules\scripts\async_poro_games.py:26> exception=ContentTypeError(RequestInfo(url=URL('https://porofessor.gg/current-games/vn/garen/queue-450'), method='GET', headers=<CIMultiDictProxy('Host': 'porofessor.gg', 'User-Agent': 'Mozilla/5.0 (Windows NT 10.0; Win64; x64) AppleWebKit/537.36 (KHTML, like Gecko) Chrome/111.0.0.0 Safari/537.36', 'Accept': '*/*', 'Accept-Encoding': 'gzip, deflate')>, real_url=URL('https://porofessor.gg/current-games/vn/garen/queue-450')), (), message='Attempt to decode JSON with unexpected mimetype: text/html; charset=utf-8', headers=<CIMultiDictProxy('Date': 'Sun, 03 Dec 2023 19:10:38 GMT', 'x-frame-options': 'SAMEORIGIN', 'fid': 'www-19', 'cv': 'CV-TL2CsKim4FFX', 'Vary': 'Accept-Encoding', 'Content-Encoding': 'gzip', 'Content-Length': '4564', 'Content-Type': 'text/html; charset=UTF-8')>)>
Traceback (most recent call last):
  File "C:\python_field\MCF\modules\scripts\async_poro_games.py", line 35, in parsing
    result = await response.text()
             ^^^^^^^^^^^^^^^^^^^^^
  File "C:\python_field\MCF\.mcfenv\Lib\site-packages\aiohttp\client_reqrep.py", line 1104, in json
    raise ContentTypeError(
aiohttp.client_exceptions.ContentTypeError: 0, message='Attempt to decode JSON with unexpected mimetype: text/html; charset=utf-8', url=URL('https://porofessor.gg/current-games/vn/garen/queue-450')
2023-12-03 22:11:31,065 ERROR Task exception was never retrieved
future: <Task finished name='Task-12' coro=<parse_games.<locals>.parsing() done, defined at C:\python_field\MCF\modules\scripts\async_poro_games.py:26> exception=ContentTypeError(RequestInfo(url=URL('https://porofessor.gg/current-games/jp/garen/queue-450'), method='GET', headers=<CIMultiDictProxy('Host': 'porofessor.gg', 'User-Agent': 'Mozilla/5.0 (Windows NT 10.0; Win64; x64) AppleWebKit/537.36 (KHTML, like Gecko) Chrome/111.0.0.0 Safari/537.36', 'Accept': '*/*', 'Accept-Encoding': 'gzip, deflate')>, real_url=URL('https://porofessor.gg/current-games/jp/garen/queue-450')), (), message='Attempt to decode JSON with unexpected mimetype: text/html; charset=utf-8', headers=<CIMultiDictProxy('Date': 'Sun, 03 Dec 2023 19:10:38 GMT', 'x-frame-options': 'SAMEORIGIN', 'fid': 'www-13', 'cv': 'CV-IR3khw2B7eZI', 'Vary': 'Accept-Encoding', 'Content-Encoding': 'gzip', 'Content-Length': '4563', 'Content-Type': 'text/html; charset=UTF-8')>)>
Traceback (most recent call last):
  File "C:\python_field\MCF\modules\scripts\async_poro_games.py", line 35, in parsing
    result = await response.text()
             ^^^^^^^^^^^^^^^^^^^^^
  File "C:\python_field\MCF\.mcfenv\Lib\site-packages\aiohttp\client_reqrep.py", line 1104, in json
    raise ContentTypeError(
aiohttp.client_exceptions.ContentTypeError: 0, message='Attempt to decode JSON with unexpected mimetype: text/html; charset=utf-8', url=URL('https://porofessor.gg/current-games/jp/garen/queue-450')
2023-12-03 22:11:31,067 ERROR Task exception was never retrieved
future: <Task finished name='Task-11' coro=<parse_games.<locals>.parsing() done, defined at C:\python_field\MCF\modules\scripts\async_poro_games.py:26> exception=ContentTypeError(RequestInfo(url=URL('https://porofessor.gg/current-games/kr/garen/queue-450'), method='GET', headers=<CIMultiDictProxy('Host': 'porofessor.gg', 'User-Agent': 'Mozilla/5.0 (Windows NT 10.0; Win64; x64) AppleWebKit/537.36 (KHTML, like Gecko) Chrome/111.0.0.0 Safari/537.36', 'Accept': '*/*', 'Accept-Encoding': 'gzip, deflate')>, real_url=URL('https://porofessor.gg/current-games/kr/garen/queue-450')), (), message='Attempt to decode JSON with unexpected mimetype: text/html; charset=utf-8', headers=<CIMultiDictProxy('Date': 'Sun, 03 Dec 2023 19:10:38 GMT', 'x-frame-options': 'SAMEORIGIN', 'fid': 'www-16', 'cv': 'CV-xtJHwh6i6jBG', 'Vary': 'Accept-Encoding', 'Content-Encoding': 'gzip', 'Content-Length': '4564', 'Content-Type': 'text/html; charset=UTF-8')>)>
Traceback (most recent call last):
  File "C:\python_field\MCF\modules\scripts\async_poro_games.py", line 35, in parsing
    result = await response.text()
             ^^^^^^^^^^^^^^^^^^^^^
  File "C:\python_field\MCF\.mcfenv\Lib\site-packages\aiohttp\client_reqrep.py", line 1104, in json
    raise ContentTypeError(
aiohttp.client_exceptions.ContentTypeError: 0, message='Attempt to decode JSON with unexpected mimetype: text/html; charset=utf-8', url=URL('https://porofessor.gg/current-games/kr/garen/queue-450')
2023-12-03 22:11:31,069 ERROR Task exception was never retrieved
future: <Task finished name='Task-9' coro=<parse_games.<locals>.parsing() done, defined at C:\python_field\MCF\modules\scripts\async_poro_games.py:26> exception=ContentTypeError(RequestInfo(url=URL('https://porofessor.gg/current-games/ru/garen/queue-450'), method='GET', headers=<CIMultiDictProxy('Host': 'porofessor.gg', 'User-Agent': 'Mozilla/5.0 (Windows NT 10.0; Win64; x64) AppleWebKit/537.36 (KHTML, like Gecko) Chrome/111.0.0.0 Safari/537.36', 'Accept': '*/*', 'Accept-Encoding': 'gzip, deflate')>, real_url=URL('https://porofessor.gg/current-games/ru/garen/queue-450')), (), message='Attempt to decode JSON with unexpected mimetype: text/html; charset=utf-8', headers=<CIMultiDictProxy('Date': 'Sun, 03 Dec 2023 19:10:38 GMT', 'x-frame-options': 'SAMEORIGIN', 'fid': 'www-2', 'cv': 'CV-pmQ3vmjXc93J', 'Vary': 'Accept-Encoding', 'Content-Encoding': 'gzip', 'Content-Length': '4564', 'Content-Type': 'text/html; charset=UTF-8')>)>
Traceback (most recent call last):
  File "C:\python_field\MCF\modules\scripts\async_poro_games.py", line 35, in parsing
    result = await response.text()
             ^^^^^^^^^^^^^^^^^^^^^
  File "C:\python_field\MCF\.mcfenv\Lib\site-packages\aiohttp\client_reqrep.py", line 1104, in json
    raise ContentTypeError(
aiohttp.client_exceptions.ContentTypeError: 0, message='Attempt to decode JSON with unexpected mimetype: text/html; charset=utf-8', url=URL('https://porofessor.gg/current-games/ru/garen/queue-450')
2023-12-03 22:11:31,071 ERROR Task exception was never retrieved
future: <Task finished name='Task-8' coro=<parse_games.<locals>.parsing() done, defined at C:\python_field\MCF\modules\scripts\async_poro_games.py:26> exception=ContentTypeError(RequestInfo(url=URL('https://porofessor.gg/current-games/tr/garen/queue-450'), method='GET', headers=<CIMultiDictProxy('Host': 'porofessor.gg', 'User-Agent': 'Mozilla/5.0 (Windows NT 10.0; Win64; x64) AppleWebKit/537.36 (KHTML, like Gecko) Chrome/111.0.0.0 Safari/537.36', 'Accept': '*/*', 'Accept-Encoding': 'gzip, deflate')>, real_url=URL('https://porofessor.gg/current-games/tr/garen/queue-450')), (), message='Attempt to decode JSON with unexpected mimetype: text/html; charset=utf-8', headers=<CIMultiDictProxy('Date': 'Sun, 03 Dec 2023 19:10:38 GMT', 'x-frame-options': 'SAMEORIGIN', 'fid': 'www-14', 'cv': 'CV-TPGasr5CIoBq', 'Vary': 'Accept-Encoding', 'Content-Encoding': 'gzip', 'Content-Length': '4563', 'Content-Type': 'text/html; charset=UTF-8')>)>
Traceback (most recent call last):
  File "C:\python_field\MCF\modules\scripts\async_poro_games.py", line 35, in parsing
    result = await response.text()
             ^^^^^^^^^^^^^^^^^^^^^
  File "C:\python_field\MCF\.mcfenv\Lib\site-packages\aiohttp\client_reqrep.py", line 1104, in json
    raise ContentTypeError(
aiohttp.client_exceptions.ContentTypeError: 0, message='Attempt to decode JSON with unexpected mimetype: text/html; charset=utf-8', url=URL('https://porofessor.gg/current-games/tr/garen/queue-450')
2023-12-03 22:11:31,073 ERROR Task exception was never retrieved
future: <Task finished name='Task-7' coro=<parse_games.<locals>.parsing() done, defined at C:\python_field\MCF\modules\scripts\async_poro_games.py:26> exception=ContentTypeError(RequestInfo(url=URL('https://porofessor.gg/current-games/eune/garen/queue-450'), method='GET', headers=<CIMultiDictProxy('Host': 'porofessor.gg', 'User-Agent': 'Mozilla/5.0 (Windows NT 10.0; Win64; x64) AppleWebKit/537.36 (KHTML, like Gecko) Chrome/111.0.0.0 Safari/537.36', 'Accept': '*/*', 'Accept-Encoding': 'gzip, deflate')>, real_url=URL('https://porofessor.gg/current-games/eune/garen/queue-450')), (), message='Attempt to decode JSON with unexpected mimetype: text/html; charset=utf-8', headers=<CIMultiDictProxy('Date': 'Sun, 03 Dec 2023 19:10:38 GMT', 'x-frame-options': 'SAMEORIGIN', 'fid': 'www-5', 'cv': 'CV-HzC9AY7InHYE', 'Vary': 'Accept-Encoding', 'Content-Encoding': 'gzip', 'Content-Length': '4567', 'Content-Type': 'text/html; charset=UTF-8')>)>
Traceback (most recent call last):
  File "C:\python_field\MCF\modules\scripts\async_poro_games.py", line 35, in parsing
    result = await response.text()
             ^^^^^^^^^^^^^^^^^^^^^
  File "C:\python_field\MCF\.mcfenv\Lib\site-packages\aiohttp\client_reqrep.py", line 1104, in json
    raise ContentTypeError(
aiohttp.client_exceptions.ContentTypeError: 0, message='Attempt to decode JSON with unexpected mimetype: text/html; charset=utf-8', url=URL('https://porofessor.gg/current-games/eune/garen/queue-450')
2023-12-03 22:11:31,075 ERROR Task exception was never retrieved
future: <Task finished name='Task-6' coro=<parse_games.<locals>.parsing() done, defined at C:\python_field\MCF\modules\scripts\async_poro_games.py:26> exception=ContentTypeError(RequestInfo(url=URL('https://porofessor.gg/current-games/oce/garen/queue-450'), method='GET', headers=<CIMultiDictProxy('Host': 'porofessor.gg', 'User-Agent': 'Mozilla/5.0 (Windows NT 10.0; Win64; x64) AppleWebKit/537.36 (KHTML, like Gecko) Chrome/111.0.0.0 Safari/537.36', 'Accept': '*/*', 'Accept-Encoding': 'gzip, deflate')>, real_url=URL('https://porofessor.gg/current-games/oce/garen/queue-450')), (), message='Attempt to decode JSON with unexpected mimetype: text/html; charset=utf-8', headers=<CIMultiDictProxy('Date': 'Sun, 03 Dec 2023 19:10:38 GMT', 'x-frame-options': 'SAMEORIGIN', 'fid': 'www-15', 'cv': 'CV-0s9st8Rfl4BF', 'Vary': 'Accept-Encoding', 'Content-Encoding': 'gzip', 'Content-Length': '4564', 'Content-Type': 'text/html; charset=UTF-8')>)>
Traceback (most recent call last):
  File "C:\python_field\MCF\modules\scripts\async_poro_games.py", line 35, in parsing
    result = await response.text()
             ^^^^^^^^^^^^^^^^^^^^^
  File "C:\python_field\MCF\.mcfenv\Lib\site-packages\aiohttp\client_reqrep.py", line 1104, in json
    raise ContentTypeError(
aiohttp.client_exceptions.ContentTypeError: 0, message='Attempt to decode JSON with unexpected mimetype: text/html; charset=utf-8', url=URL('https://porofessor.gg/current-games/oce/garen/queue-450')
2023-12-03 22:11:31,077 ERROR Task exception was never retrieved
future: <Task finished name='Task-5' coro=<parse_games.<locals>.parsing() done, defined at C:\python_field\MCF\modules\scripts\async_poro_games.py:26> exception=ContentTypeError(RequestInfo(url=URL('https://porofessor.gg/current-games/las/garen/queue-450'), method='GET', headers=<CIMultiDictProxy('Host': 'porofessor.gg', 'User-Agent': 'Mozilla/5.0 (Windows NT 10.0; Win64; x64) AppleWebKit/537.36 (KHTML, like Gecko) Chrome/111.0.0.0 Safari/537.36', 'Accept': '*/*', 'Accept-Encoding': 'gzip, deflate')>, real_url=URL('https://porofessor.gg/current-games/las/garen/queue-450')), (), message='Attempt to decode JSON with unexpected mimetype: text/html; charset=utf-8', headers=<CIMultiDictProxy('Date': 'Sun, 03 Dec 2023 19:10:38 GMT', 'x-frame-options': 'SAMEORIGIN', 'fid': 'www-0', 'cv': 'CV-dr8G3Az3Njqj', 'Vary': 'Accept-Encoding', 'Content-Encoding': 'gzip', 'Content-Length': '4564', 'Content-Type': 'text/html; charset=UTF-8')>)>
Traceback (most recent call last):
  File "C:\python_field\MCF\modules\scripts\async_poro_games.py", line 35, in parsing
    result = await response.text()
             ^^^^^^^^^^^^^^^^^^^^^
  File "C:\python_field\MCF\.mcfenv\Lib\site-packages\aiohttp\client_reqrep.py", line 1104, in json
    raise ContentTypeError(
aiohttp.client_exceptions.ContentTypeError: 0, message='Attempt to decode JSON with unexpected mimetype: text/html; charset=utf-8', url=URL('https://porofessor.gg/current-games/las/garen/queue-450')
2023-12-03 22:11:31,079 ERROR Task exception was never retrieved
future: <Task finished name='Task-4' coro=<parse_games.<locals>.parsing() done, defined at C:\python_field\MCF\modules\scripts\async_poro_games.py:26> exception=ContentTypeError(RequestInfo(url=URL('https://porofessor.gg/current-games/na/garen/queue-450'), method='GET', headers=<CIMultiDictProxy('Host': 'porofessor.gg', 'User-Agent': 'Mozilla/5.0 (Windows NT 10.0; Win64; x64) AppleWebKit/537.36 (KHTML, like Gecko) Chrome/111.0.0.0 Safari/537.36', 'Accept': '*/*', 'Accept-Encoding': 'gzip, deflate')>, real_url=URL('https://porofessor.gg/current-games/na/garen/queue-450')), (), message='Attempt to decode JSON with unexpected mimetype: text/html; charset=utf-8', headers=<CIMultiDictProxy('Date': 'Sun, 03 Dec 2023 19:10:38 GMT', 'x-frame-options': 'SAMEORIGIN', 'fid': 'www-5', 'cv': 'CV-L4NfeOxRUJRn', 'Vary': 'Accept-Encoding', 'Content-Encoding': 'gzip', 'Content-Length': '4563', 'Content-Type': 'text/html; charset=UTF-8')>)>
Traceback (most recent call last):
  File "C:\python_field\MCF\modules\scripts\async_poro_games.py", line 35, in parsing
    result = await response.text()
             ^^^^^^^^^^^^^^^^^^^^^
  File "C:\python_field\MCF\.mcfenv\Lib\site-packages\aiohttp\client_reqrep.py", line 1104, in json
    raise ContentTypeError(
aiohttp.client_exceptions.ContentTypeError: 0, message='Attempt to decode JSON with unexpected mimetype: text/html; charset=utf-8', url=URL('https://porofessor.gg/current-games/na/garen/queue-450')
2023-12-03 22:11:31,081 ERROR Task exception was never retrieved
future: <Task finished name='Task-3' coro=<parse_games.<locals>.parsing() done, defined at C:\python_field\MCF\modules\scripts\async_poro_games.py:26> exception=ContentTypeError(RequestInfo(url=URL('https://porofessor.gg/current-games/lan/garen/queue-450'), method='GET', headers=<CIMultiDictProxy('Host': 'porofessor.gg', 'User-Agent': 'Mozilla/5.0 (Windows NT 10.0; Win64; x64) AppleWebKit/537.36 (KHTML, like Gecko) Chrome/111.0.0.0 Safari/537.36', 'Accept': '*/*', 'Accept-Encoding': 'gzip, deflate')>, real_url=URL('https://porofessor.gg/current-games/lan/garen/queue-450')), (), message='Attempt to decode JSON with unexpected mimetype: text/html; charset=utf-8', headers=<CIMultiDictProxy('Date': 'Sun, 03 Dec 2023 19:10:38 GMT', 'x-frame-options': 'SAMEORIGIN', 'fid': 'www-10', 'cv': 'CV-BLVxWdeeGys8', 'Vary': 'Accept-Encoding', 'Content-Encoding': 'gzip', 'Content-Length': '4564', 'Content-Type': 'text/html; charset=UTF-8')>)>
Traceback (most recent call last):
  File "C:\python_field\MCF\modules\scripts\async_poro_games.py", line 35, in parsing
    result = await response.text()
             ^^^^^^^^^^^^^^^^^^^^^
  File "C:\python_field\MCF\.mcfenv\Lib\site-packages\aiohttp\client_reqrep.py", line 1104, in json
    raise ContentTypeError(
aiohttp.client_exceptions.ContentTypeError: 0, message='Attempt to decode JSON with unexpected mimetype: text/html; charset=utf-8', url=URL('https://porofessor.gg/current-games/lan/garen/queue-450')
2023-12-03 22:12:04,685 ERROR Task exception was never retrieved
future: <Task finished name='Task-17' coro=<parse_games.<locals>.parsing() done, defined at C:\python_field\MCF\modules\scripts\async_poro_games.py:26> exception=TypeError('list indices must be integers or slices, not str')>
Traceback (most recent call last):
  File "C:\python_field\MCF\modules\scripts\async_poro_games.py", line 84, in parsing
    MCFStorage.write_data(route=('MatchesRift', region), value=featured_games)
  File "C:\python_field\MCF\mcf_data.py", line 170, in write_data
    data[route[0]][route[1]] = value
    ^^^^^^^^^^^^^^^^^^^^^^^^
TypeError: list indices must be integers or slices, not str
2023-12-03 22:12:04,691 ERROR Task exception was never retrieved
future: <Task finished name='Task-16' coro=<parse_games.<locals>.parsing() done, defined at C:\python_field\MCF\modules\scripts\async_poro_games.py:26> exception=TypeError('list indices must be integers or slices, not str')>
Traceback (most recent call last):
  File "C:\python_field\MCF\modules\scripts\async_poro_games.py", line 84, in parsing
    MCFStorage.write_data(route=('MatchesRift', region), value=featured_games)
  File "C:\python_field\MCF\mcf_data.py", line 170, in write_data
    data[route[0]][route[1]] = value
    ^^^^^^^^^^^^^^^^^^^^^^^^
TypeError: list indices must be integers or slices, not str
2023-12-03 22:12:04,693 ERROR Task exception was never retrieved
future: <Task finished name='Task-15' coro=<parse_games.<locals>.parsing() done, defined at C:\python_field\MCF\modules\scripts\async_poro_games.py:26> exception=TypeError('list indices must be integers or slices, not str')>
Traceback (most recent call last):
  File "C:\python_field\MCF\modules\scripts\async_poro_games.py", line 84, in parsing
    MCFStorage.write_data(route=('MatchesRift', region), value=featured_games)
  File "C:\python_field\MCF\mcf_data.py", line 170, in write_data
    data[route[0]][route[1]] = value
    ^^^^^^^^^^^^^^^^^^^^^^^^
TypeError: list indices must be integers or slices, not str
2023-12-03 22:12:04,695 ERROR Task exception was never retrieved
future: <Task finished name='Task-14' coro=<parse_games.<locals>.parsing() done, defined at C:\python_field\MCF\modules\scripts\async_poro_games.py:26> exception=TypeError('list indices must be integers or slices, not str')>
Traceback (most recent call last):
  File "C:\python_field\MCF\modules\scripts\async_poro_games.py", line 84, in parsing
    MCFStorage.write_data(route=('MatchesRift', region), value=featured_games)
  File "C:\python_field\MCF\mcf_data.py", line 170, in write_data
    data[route[0]][route[1]] = value
    ^^^^^^^^^^^^^^^^^^^^^^^^
TypeError: list indices must be integers or slices, not str
2023-12-03 22:12:04,697 ERROR Task exception was never retrieved
future: <Task finished name='Task-13' coro=<parse_games.<locals>.parsing() done, defined at C:\python_field\MCF\modules\scripts\async_poro_games.py:26> exception=TypeError('list indices must be integers or slices, not str')>
Traceback (most recent call last):
  File "C:\python_field\MCF\modules\scripts\async_poro_games.py", line 84, in parsing
    MCFStorage.write_data(route=('MatchesRift', region), value=featured_games)
  File "C:\python_field\MCF\mcf_data.py", line 170, in write_data
    data[route[0]][route[1]] = value
    ^^^^^^^^^^^^^^^^^^^^^^^^
TypeError: list indices must be integers or slices, not str
2023-12-03 22:12:04,698 ERROR Task exception was never retrieved
future: <Task finished name='Task-12' coro=<parse_games.<locals>.parsing() done, defined at C:\python_field\MCF\modules\scripts\async_poro_games.py:26> exception=TypeError('list indices must be integers or slices, not str')>
Traceback (most recent call last):
  File "C:\python_field\MCF\modules\scripts\async_poro_games.py", line 84, in parsing
    MCFStorage.write_data(route=('MatchesRift', region), value=featured_games)
  File "C:\python_field\MCF\mcf_data.py", line 170, in write_data
    data[route[0]][route[1]] = value
    ^^^^^^^^^^^^^^^^^^^^^^^^
TypeError: list indices must be integers or slices, not str
2023-12-03 22:12:04,700 ERROR Task exception was never retrieved
future: <Task finished name='Task-11' coro=<parse_games.<locals>.parsing() done, defined at C:\python_field\MCF\modules\scripts\async_poro_games.py:26> exception=TypeError('list indices must be integers or slices, not str')>
Traceback (most recent call last):
  File "C:\python_field\MCF\modules\scripts\async_poro_games.py", line 84, in parsing
    MCFStorage.write_data(route=('MatchesRift', region), value=featured_games)
  File "C:\python_field\MCF\mcf_data.py", line 170, in write_data
    data[route[0]][route[1]] = value
    ^^^^^^^^^^^^^^^^^^^^^^^^
TypeError: list indices must be integers or slices, not str
2023-12-03 22:12:04,702 ERROR Task exception was never retrieved
future: <Task finished name='Task-10' coro=<parse_games.<locals>.parsing() done, defined at C:\python_field\MCF\modules\scripts\async_poro_games.py:26> exception=TypeError('list indices must be integers or slices, not str')>
Traceback (most recent call last):
  File "C:\python_field\MCF\modules\scripts\async_poro_games.py", line 84, in parsing
    MCFStorage.write_data(route=('MatchesRift', region), value=featured_games)
  File "C:\python_field\MCF\mcf_data.py", line 170, in write_data
    data[route[0]][route[1]] = value
    ^^^^^^^^^^^^^^^^^^^^^^^^
TypeError: list indices must be integers or slices, not str
2023-12-03 22:12:04,703 ERROR Task exception was never retrieved
future: <Task finished name='Task-9' coro=<parse_games.<locals>.parsing() done, defined at C:\python_field\MCF\modules\scripts\async_poro_games.py:26> exception=TypeError('list indices must be integers or slices, not str')>
Traceback (most recent call last):
  File "C:\python_field\MCF\modules\scripts\async_poro_games.py", line 84, in parsing
    MCFStorage.write_data(route=('MatchesRift', region), value=featured_games)
  File "C:\python_field\MCF\mcf_data.py", line 170, in write_data
    data[route[0]][route[1]] = value
    ^^^^^^^^^^^^^^^^^^^^^^^^
TypeError: list indices must be integers or slices, not str
2023-12-03 22:12:04,705 ERROR Task exception was never retrieved
future: <Task finished name='Task-8' coro=<parse_games.<locals>.parsing() done, defined at C:\python_field\MCF\modules\scripts\async_poro_games.py:26> exception=TypeError('list indices must be integers or slices, not str')>
Traceback (most recent call last):
  File "C:\python_field\MCF\modules\scripts\async_poro_games.py", line 84, in parsing
    MCFStorage.write_data(route=('MatchesRift', region), value=featured_games)
  File "C:\python_field\MCF\mcf_data.py", line 170, in write_data
    data[route[0]][route[1]] = value
    ^^^^^^^^^^^^^^^^^^^^^^^^
TypeError: list indices must be integers or slices, not str
2023-12-03 22:12:04,707 ERROR Task exception was never retrieved
future: <Task finished name='Task-7' coro=<parse_games.<locals>.parsing() done, defined at C:\python_field\MCF\modules\scripts\async_poro_games.py:26> exception=TypeError('list indices must be integers or slices, not str')>
Traceback (most recent call last):
  File "C:\python_field\MCF\modules\scripts\async_poro_games.py", line 84, in parsing
    MCFStorage.write_data(route=('MatchesRift', region), value=featured_games)
  File "C:\python_field\MCF\mcf_data.py", line 170, in write_data
    data[route[0]][route[1]] = value
    ^^^^^^^^^^^^^^^^^^^^^^^^
TypeError: list indices must be integers or slices, not str
2023-12-03 22:12:04,709 ERROR Task exception was never retrieved
future: <Task finished name='Task-6' coro=<parse_games.<locals>.parsing() done, defined at C:\python_field\MCF\modules\scripts\async_poro_games.py:26> exception=TypeError('list indices must be integers or slices, not str')>
Traceback (most recent call last):
  File "C:\python_field\MCF\modules\scripts\async_poro_games.py", line 84, in parsing
    MCFStorage.write_data(route=('MatchesRift', region), value=featured_games)
  File "C:\python_field\MCF\mcf_data.py", line 170, in write_data
    data[route[0]][route[1]] = value
    ^^^^^^^^^^^^^^^^^^^^^^^^
TypeError: list indices must be integers or slices, not str
2023-12-03 22:12:04,710 ERROR Task exception was never retrieved
future: <Task finished name='Task-5' coro=<parse_games.<locals>.parsing() done, defined at C:\python_field\MCF\modules\scripts\async_poro_games.py:26> exception=TypeError('list indices must be integers or slices, not str')>
Traceback (most recent call last):
  File "C:\python_field\MCF\modules\scripts\async_poro_games.py", line 84, in parsing
    MCFStorage.write_data(route=('MatchesRift', region), value=featured_games)
  File "C:\python_field\MCF\mcf_data.py", line 170, in write_data
    data[route[0]][route[1]] = value
    ^^^^^^^^^^^^^^^^^^^^^^^^
TypeError: list indices must be integers or slices, not str
2023-12-03 22:12:04,712 ERROR Task exception was never retrieved
future: <Task finished name='Task-4' coro=<parse_games.<locals>.parsing() done, defined at C:\python_field\MCF\modules\scripts\async_poro_games.py:26> exception=TypeError('list indices must be integers or slices, not str')>
Traceback (most recent call last):
  File "C:\python_field\MCF\modules\scripts\async_poro_games.py", line 84, in parsing
    MCFStorage.write_data(route=('MatchesRift', region), value=featured_games)
  File "C:\python_field\MCF\mcf_data.py", line 170, in write_data
    data[route[0]][route[1]] = value
    ^^^^^^^^^^^^^^^^^^^^^^^^
TypeError: list indices must be integers or slices, not str
2023-12-03 22:12:04,714 ERROR Task exception was never retrieved
future: <Task finished name='Task-3' coro=<parse_games.<locals>.parsing() done, defined at C:\python_field\MCF\modules\scripts\async_poro_games.py:26> exception=TypeError('list indices must be integers or slices, not str')>
Traceback (most recent call last):
  File "C:\python_field\MCF\modules\scripts\async_poro_games.py", line 84, in parsing
    MCFStorage.write_data(route=('MatchesRift', region), value=featured_games)
  File "C:\python_field\MCF\mcf_data.py", line 170, in write_data
    data[route[0]][route[1]] = value
    ^^^^^^^^^^^^^^^^^^^^^^^^
TypeError: list indices must be integers or slices, not str
2023-12-03 22:29:28,304 ERROR Task exception was never retrieved
future: <Task finished name='Task-8' coro=<parse_games.<locals>.parsing() done, defined at C:\python_field\MCF\modules\scripts\async_poro_games.py:26> exception=UnboundLocalError("cannot access local variable 'result' where it is not associated with a value")>
Traceback (most recent call last):
  File "C:\python_field\MCF\modules\scripts\async_poro_games.py", line 33, in parsing
    open(f'{region}_porodata.html', 'w+', encoding='utf8').write(result)
                                                                 ^^^^^^
UnboundLocalError: cannot access local variable 'result' where it is not associated with a value
2023-12-03 22:29:28,306 ERROR Task exception was never retrieved
future: <Task finished name='Task-5' coro=<parse_games.<locals>.parsing() done, defined at C:\python_field\MCF\modules\scripts\async_poro_games.py:26> exception=UnboundLocalError("cannot access local variable 'result' where it is not associated with a value")>
Traceback (most recent call last):
  File "C:\python_field\MCF\modules\scripts\async_poro_games.py", line 33, in parsing
    open(f'{region}_porodata.html', 'w+', encoding='utf8').write(result)
                                                                 ^^^^^^
UnboundLocalError: cannot access local variable 'result' where it is not associated with a value
2023-12-03 22:32:45,859 ERROR Task exception was never retrieved
future: <Task finished name='Task-17' coro=<parse_games.<locals>.parsing() done, defined at C:\python_field\MCF\modules\scripts\async_poro_games.py:25> exception=TypeError("unsupported operand type(s) for ** or pow(): 'str' and 'dict'")>
Traceback (most recent call last):
  File "C:\python_field\MCF\modules\scripts\async_poro_games.py", line 34, in parsing
    async with session.get(url=URL_PORO_BY_REGIONS.format(region=region, champion=champion)
                               ^^^^^^^^^^^^^^^^^^^^^^^^^^^^^^^^^^^^^^^^^^^^^^^^^^^^^^^^^^^^
TypeError: unsupported operand type(s) for ** or pow(): 'str' and 'dict'
2023-12-03 22:32:45,861 ERROR Task exception was never retrieved
future: <Task finished name='Task-16' coro=<parse_games.<locals>.parsing() done, defined at C:\python_field\MCF\modules\scripts\async_poro_games.py:25> exception=TypeError("unsupported operand type(s) for ** or pow(): 'str' and 'dict'")>
Traceback (most recent call last):
  File "C:\python_field\MCF\modules\scripts\async_poro_games.py", line 34, in parsing
    async with session.get(url=URL_PORO_BY_REGIONS.format(region=region, champion=champion)
                               ^^^^^^^^^^^^^^^^^^^^^^^^^^^^^^^^^^^^^^^^^^^^^^^^^^^^^^^^^^^^
TypeError: unsupported operand type(s) for ** or pow(): 'str' and 'dict'
2023-12-03 22:32:45,862 ERROR Task exception was never retrieved
future: <Task finished name='Task-15' coro=<parse_games.<locals>.parsing() done, defined at C:\python_field\MCF\modules\scripts\async_poro_games.py:25> exception=TypeError("unsupported operand type(s) for ** or pow(): 'str' and 'dict'")>
Traceback (most recent call last):
  File "C:\python_field\MCF\modules\scripts\async_poro_games.py", line 34, in parsing
    async with session.get(url=URL_PORO_BY_REGIONS.format(region=region, champion=champion)
                               ^^^^^^^^^^^^^^^^^^^^^^^^^^^^^^^^^^^^^^^^^^^^^^^^^^^^^^^^^^^^
TypeError: unsupported operand type(s) for ** or pow(): 'str' and 'dict'
2023-12-03 22:32:45,863 ERROR Task exception was never retrieved
future: <Task finished name='Task-14' coro=<parse_games.<locals>.parsing() done, defined at C:\python_field\MCF\modules\scripts\async_poro_games.py:25> exception=TypeError("unsupported operand type(s) for ** or pow(): 'str' and 'dict'")>
Traceback (most recent call last):
  File "C:\python_field\MCF\modules\scripts\async_poro_games.py", line 34, in parsing
    async with session.get(url=URL_PORO_BY_REGIONS.format(region=region, champion=champion)
                               ^^^^^^^^^^^^^^^^^^^^^^^^^^^^^^^^^^^^^^^^^^^^^^^^^^^^^^^^^^^^
TypeError: unsupported operand type(s) for ** or pow(): 'str' and 'dict'
2023-12-03 22:32:45,864 ERROR Task exception was never retrieved
future: <Task finished name='Task-13' coro=<parse_games.<locals>.parsing() done, defined at C:\python_field\MCF\modules\scripts\async_poro_games.py:25> exception=TypeError("unsupported operand type(s) for ** or pow(): 'str' and 'dict'")>
Traceback (most recent call last):
  File "C:\python_field\MCF\modules\scripts\async_poro_games.py", line 34, in parsing
    async with session.get(url=URL_PORO_BY_REGIONS.format(region=region, champion=champion)
                               ^^^^^^^^^^^^^^^^^^^^^^^^^^^^^^^^^^^^^^^^^^^^^^^^^^^^^^^^^^^^
TypeError: unsupported operand type(s) for ** or pow(): 'str' and 'dict'
2023-12-03 22:32:45,865 ERROR Task exception was never retrieved
future: <Task finished name='Task-12' coro=<parse_games.<locals>.parsing() done, defined at C:\python_field\MCF\modules\scripts\async_poro_games.py:25> exception=TypeError("unsupported operand type(s) for ** or pow(): 'str' and 'dict'")>
Traceback (most recent call last):
  File "C:\python_field\MCF\modules\scripts\async_poro_games.py", line 34, in parsing
    async with session.get(url=URL_PORO_BY_REGIONS.format(region=region, champion=champion)
                               ^^^^^^^^^^^^^^^^^^^^^^^^^^^^^^^^^^^^^^^^^^^^^^^^^^^^^^^^^^^^
TypeError: unsupported operand type(s) for ** or pow(): 'str' and 'dict'
2023-12-03 22:32:45,866 ERROR Task exception was never retrieved
future: <Task finished name='Task-11' coro=<parse_games.<locals>.parsing() done, defined at C:\python_field\MCF\modules\scripts\async_poro_games.py:25> exception=TypeError("unsupported operand type(s) for ** or pow(): 'str' and 'dict'")>
Traceback (most recent call last):
  File "C:\python_field\MCF\modules\scripts\async_poro_games.py", line 34, in parsing
    async with session.get(url=URL_PORO_BY_REGIONS.format(region=region, champion=champion)
                               ^^^^^^^^^^^^^^^^^^^^^^^^^^^^^^^^^^^^^^^^^^^^^^^^^^^^^^^^^^^^
TypeError: unsupported operand type(s) for ** or pow(): 'str' and 'dict'
2023-12-03 22:32:45,867 ERROR Task exception was never retrieved
future: <Task finished name='Task-10' coro=<parse_games.<locals>.parsing() done, defined at C:\python_field\MCF\modules\scripts\async_poro_games.py:25> exception=TypeError("unsupported operand type(s) for ** or pow(): 'str' and 'dict'")>
Traceback (most recent call last):
  File "C:\python_field\MCF\modules\scripts\async_poro_games.py", line 34, in parsing
    async with session.get(url=URL_PORO_BY_REGIONS.format(region=region, champion=champion)
                               ^^^^^^^^^^^^^^^^^^^^^^^^^^^^^^^^^^^^^^^^^^^^^^^^^^^^^^^^^^^^
TypeError: unsupported operand type(s) for ** or pow(): 'str' and 'dict'
2023-12-03 22:32:45,868 ERROR Task exception was never retrieved
future: <Task finished name='Task-9' coro=<parse_games.<locals>.parsing() done, defined at C:\python_field\MCF\modules\scripts\async_poro_games.py:25> exception=TypeError("unsupported operand type(s) for ** or pow(): 'str' and 'dict'")>
Traceback (most recent call last):
  File "C:\python_field\MCF\modules\scripts\async_poro_games.py", line 34, in parsing
    async with session.get(url=URL_PORO_BY_REGIONS.format(region=region, champion=champion)
                               ^^^^^^^^^^^^^^^^^^^^^^^^^^^^^^^^^^^^^^^^^^^^^^^^^^^^^^^^^^^^
TypeError: unsupported operand type(s) for ** or pow(): 'str' and 'dict'
2023-12-03 22:32:45,869 ERROR Task exception was never retrieved
future: <Task finished name='Task-8' coro=<parse_games.<locals>.parsing() done, defined at C:\python_field\MCF\modules\scripts\async_poro_games.py:25> exception=TypeError("unsupported operand type(s) for ** or pow(): 'str' and 'dict'")>
Traceback (most recent call last):
  File "C:\python_field\MCF\modules\scripts\async_poro_games.py", line 34, in parsing
    async with session.get(url=URL_PORO_BY_REGIONS.format(region=region, champion=champion)
                               ^^^^^^^^^^^^^^^^^^^^^^^^^^^^^^^^^^^^^^^^^^^^^^^^^^^^^^^^^^^^
TypeError: unsupported operand type(s) for ** or pow(): 'str' and 'dict'
2023-12-03 22:32:45,870 ERROR Task exception was never retrieved
future: <Task finished name='Task-7' coro=<parse_games.<locals>.parsing() done, defined at C:\python_field\MCF\modules\scripts\async_poro_games.py:25> exception=TypeError("unsupported operand type(s) for ** or pow(): 'str' and 'dict'")>
Traceback (most recent call last):
  File "C:\python_field\MCF\modules\scripts\async_poro_games.py", line 34, in parsing
    async with session.get(url=URL_PORO_BY_REGIONS.format(region=region, champion=champion)
                               ^^^^^^^^^^^^^^^^^^^^^^^^^^^^^^^^^^^^^^^^^^^^^^^^^^^^^^^^^^^^
TypeError: unsupported operand type(s) for ** or pow(): 'str' and 'dict'
2023-12-03 22:32:45,871 ERROR Task exception was never retrieved
future: <Task finished name='Task-6' coro=<parse_games.<locals>.parsing() done, defined at C:\python_field\MCF\modules\scripts\async_poro_games.py:25> exception=TypeError("unsupported operand type(s) for ** or pow(): 'str' and 'dict'")>
Traceback (most recent call last):
  File "C:\python_field\MCF\modules\scripts\async_poro_games.py", line 34, in parsing
    async with session.get(url=URL_PORO_BY_REGIONS.format(region=region, champion=champion)
                               ^^^^^^^^^^^^^^^^^^^^^^^^^^^^^^^^^^^^^^^^^^^^^^^^^^^^^^^^^^^^
TypeError: unsupported operand type(s) for ** or pow(): 'str' and 'dict'
2023-12-03 22:32:45,872 ERROR Task exception was never retrieved
future: <Task finished name='Task-5' coro=<parse_games.<locals>.parsing() done, defined at C:\python_field\MCF\modules\scripts\async_poro_games.py:25> exception=TypeError("unsupported operand type(s) for ** or pow(): 'str' and 'dict'")>
Traceback (most recent call last):
  File "C:\python_field\MCF\modules\scripts\async_poro_games.py", line 34, in parsing
    async with session.get(url=URL_PORO_BY_REGIONS.format(region=region, champion=champion)
                               ^^^^^^^^^^^^^^^^^^^^^^^^^^^^^^^^^^^^^^^^^^^^^^^^^^^^^^^^^^^^
TypeError: unsupported operand type(s) for ** or pow(): 'str' and 'dict'
2023-12-03 22:32:45,873 ERROR Task exception was never retrieved
future: <Task finished name='Task-4' coro=<parse_games.<locals>.parsing() done, defined at C:\python_field\MCF\modules\scripts\async_poro_games.py:25> exception=TypeError("unsupported operand type(s) for ** or pow(): 'str' and 'dict'")>
Traceback (most recent call last):
  File "C:\python_field\MCF\modules\scripts\async_poro_games.py", line 34, in parsing
    async with session.get(url=URL_PORO_BY_REGIONS.format(region=region, champion=champion)
                               ^^^^^^^^^^^^^^^^^^^^^^^^^^^^^^^^^^^^^^^^^^^^^^^^^^^^^^^^^^^^
TypeError: unsupported operand type(s) for ** or pow(): 'str' and 'dict'
2023-12-03 22:32:45,874 ERROR Task exception was never retrieved
future: <Task finished name='Task-3' coro=<parse_games.<locals>.parsing() done, defined at C:\python_field\MCF\modules\scripts\async_poro_games.py:25> exception=TypeError("unsupported operand type(s) for ** or pow(): 'str' and 'dict'")>
Traceback (most recent call last):
  File "C:\python_field\MCF\modules\scripts\async_poro_games.py", line 34, in parsing
    async with session.get(url=URL_PORO_BY_REGIONS.format(region=region, champion=champion)
                               ^^^^^^^^^^^^^^^^^^^^^^^^^^^^^^^^^^^^^^^^^^^^^^^^^^^^^^^^^^^^
TypeError: unsupported operand type(s) for ** or pow(): 'str' and 'dict'
