2023-03-31 11:08:15,061 ERROR list index out of range
Traceback (most recent call last):
  File "C:\_PyPr\MCF_ARAM_dev\mcf_dev.py", line 37, in wrapper
    result = func(*args, **kwargs)
  File "C:\_PyPr\MCF_ARAM_dev\mcf_dev.py", line 364, in parsePoroGames
    result = PoroAPI.get_poro_games(red_champion=converted_champion, gamemode=event)
  File "C:\_PyPr\MCF_ARAM_dev\mcf_api.py", line 156, in get_poro_games
    ids = [int(str(ids.get('class')).split('-')[1]) for ids in game[0:5]]
  File "C:\_PyPr\MCF_ARAM_dev\mcf_api.py", line 156, in <listcomp>
    ids = [int(str(ids.get('class')).split('-')[1]) for ids in game[0:5]]
IndexError: list index out of range
2023-03-31 11:09:23,344 ERROR list index out of range
Traceback (most recent call last):
  File "C:\_PyPr\MCF_ARAM_dev\mcf_dev.py", line 37, in wrapper
    result = func(*args, **kwargs)
  File "C:\_PyPr\MCF_ARAM_dev\mcf_dev.py", line 364, in parsePoroGames
    result = PoroAPI.get_poro_games(red_champion=converted_champion, gamemode=event)
  File "C:\_PyPr\MCF_ARAM_dev\mcf_api.py", line 156, in get_poro_games
    ids = [int(str(ids.get('class')).split('-')[1]) for ids in game[0:5]]
  File "C:\_PyPr\MCF_ARAM_dev\mcf_api.py", line 156, in <listcomp>
    ids = [int(str(ids.get('class')).split('-')[1]) for ids in game[0:5]]
IndexError: list index out of range
2023-03-31 11:09:30,681 ERROR list index out of range
Traceback (most recent call last):
  File "C:\_PyPr\MCF_ARAM_dev\mcf_dev.py", line 37, in wrapper
    result = func(*args, **kwargs)
  File "C:\_PyPr\MCF_ARAM_dev\mcf_dev.py", line 364, in parsePoroGames
    result = PoroAPI.get_poro_games(red_champion=converted_champion, gamemode=event)
  File "C:\_PyPr\MCF_ARAM_dev\mcf_api.py", line 156, in get_poro_games
    ids = [int(str(ids.get('class')).split('-')[1]) for ids in game[0:5]]
  File "C:\_PyPr\MCF_ARAM_dev\mcf_api.py", line 156, in <listcomp>
    ids = [int(str(ids.get('class')).split('-')[1]) for ids in game[0:5]]
IndexError: list index out of range
2023-05-27 05:17:58,836 ERROR No module named 'mcf_build_dev'
Traceback (most recent call last):
  File "C:\_PyPr\MCF_ARAM\mcf_main.py", line 37, in wrapper
    result = func(*args, **kwargs)
             ^^^^^^^^^^^^^^^^^^^^^
  File "C:\_PyPr\MCF_ARAM\mcf_main.py", line 371, in parseAramGames
    from modules.GamesOnline import parsing_aram_api
  File "C:\_PyPr\MCF_ARAM\modules\GamesOnline.py", line 9, in <module>
    from mcf_build_dev import REGIONS_TUPLE, ELO_SYMBOLS
ModuleNotFoundError: No module named 'mcf_build_dev'
2023-05-27 05:21:05,096 ERROR name 'sw_afters' is not defined
Traceback (most recent call last):
  File "C:\_PyPr\MCF_ARAM\mcf_main.py", line 37, in wrapper
    result = func(*args, **kwargs)
             ^^^^^^^^^^^^^^^^^^^^^
  File "C:\_PyPr\MCF_ARAM\mcf_main.py", line 578, in runMainParser
    showMainInfo(text='Searching..')
  File "C:\_PyPr\MCF_ARAM\mcf_main.py", line 194, in showMainInfo
    if sw_afters['info'][0] is not None:
       ^^^^^^^^^
NameError: name 'sw_afters' is not defined
2023-06-20 11:48:50,581 ERROR Short

2023-06-20 11:48:54,605 ERROR Short

2023-06-20 11:48:58,473 ERROR list index out of range

2023-06-20 11:49:06,740 ERROR list index out of range

2023-06-20 11:49:18,724 ERROR list index out of range
Traceback (most recent call last):
  File "C:\_PyPr\New_MCF\mcf_riot_api.py", line 43, in wrapper
    result = func(*args, **kwargs)
             ^^^^^^^^^^^^^^^^^^^^^
  File "C:\_PyPr\New_MCF\mcf_riot_api.py", line 155, in get_poro_games
    ids = [int(str(ids.get('class')).split('-')[1]) for ids in game[0:5]]
          ^^^^^^^^^^^^^^^^^^^^^^^^^^^^^^^^^^^^^^^^^^^^^^^^^^^^^^^^^^^^^^^
  File "C:\_PyPr\New_MCF\mcf_riot_api.py", line 155, in <listcomp>
    ids = [int(str(ids.get('class')).split('-')[1]) for ids in game[0:5]]
               ~~~~~~~~~~~~~~~~~~~~~~~~~~~~~~~~^^^
IndexError: list index out of range
2023-06-20 11:49:57,669 ERROR list index out of range
Traceback (most recent call last):
  File "C:\_PyPr\New_MCF\mcf_riot_api.py", line 43, in wrapper
    result = func(*args, **kwargs)
             ^^^^^^^^^^^^^^^^^^^^^
  File "C:\_PyPr\New_MCF\mcf_riot_api.py", line 155, in get_poro_games
    ids = [int(str(ids.get('class')).split('-')[1]) for ids in game[0:5]]
          ^^^^^^^^^^^^^^^^^^^^^^^^^^^^^^^^^^^^^^^^^^^^^^^^^^^^^^^^^^^^^^^
  File "C:\_PyPr\New_MCF\mcf_riot_api.py", line 155, in <listcomp>
    ids = [int(str(ids.get('class')).split('-')[1]) for ids in game[0:5]]
               ~~~~~~~~~~~~~~~~~~~~~~~~~~~~~~~~^^^
IndexError: list index out of range
2023-06-20 11:51:11,591 ERROR Short
Traceback (most recent call last):
  File "C:\_PyPr\New_MCF\mcf_riot_api.py", line 43, in wrapper
    result = func(*args, **kwargs)
             ^^^^^^^^^^^^^^^^^^^^^
  File "C:\_PyPr\New_MCF\mcf_riot_api.py", line 111, in get_poro_games
    raise MCFException('Short')
mcf_build.MCFException: Short
2023-06-20 11:59:38,714 ERROR name 'ids' is not defined
Traceback (most recent call last):
  File "C:\_PyPr\New_MCF\mcf_riot_api.py", line 44, in wrapper
    result = func(*args, **kwargs)
             ^^^^^^^^^^^^^^^^^^^^^
  File "C:\_PyPr\New_MCF\mcf_riot_api.py", line 158, in get_poro_games
    converted_ids = [ALL_CHAMPIONS_IDs.get(i) for i in ids]
                                                       ^^^
NameError: name 'ids' is not defined
2023-06-20 12:01:20,191 ERROR 'str' object has no attribute 'startwidth'
Traceback (most recent call last):
  File "C:\_PyPr\New_MCF\mcf_riot_api.py", line 44, in wrapper
    result = func(*args, **kwargs)
             ^^^^^^^^^^^^^^^^^^^^^
  File "C:\_PyPr\New_MCF\mcf_riot_api.py", line 155, in get_poro_games
    if not game.get('class')[0].startwidth('champion'):
           ^^^^^^^^^^^^^^^^^^^^^^^^^^^^^^^
AttributeError: 'str' object has no attribute 'startwidth'
2023-06-20 12:01:32,731 ERROR 'str' object has no attribute 'startwith'
Traceback (most recent call last):
  File "C:\_PyPr\New_MCF\mcf_riot_api.py", line 44, in wrapper
    result = func(*args, **kwargs)
             ^^^^^^^^^^^^^^^^^^^^^
  File "C:\_PyPr\New_MCF\mcf_riot_api.py", line 155, in get_poro_games
    if not game.get('class')[0].startwith('champion'):
           ^^^^^^^^^^^^^^^^^^^^^^^^^^^^^^
AttributeError: 'str' object has no attribute 'startwith'
2023-06-20 12:02:54,180 ERROR ResultSet object has no attribute 'get'. You're probably treating a list of elements like a single element. Did you call find_all() when you meant to call find()?
Traceback (most recent call last):
  File "C:\_PyPr\New_MCF\mcf_riot_api.py", line 44, in wrapper
    result = func(*args, **kwargs)
             ^^^^^^^^^^^^^^^^^^^^^
  File "C:\_PyPr\New_MCF\mcf_riot_api.py", line 156, in get_poro_games
    if not game.get('class')[0].startswith('champion'):
           ^^^^^^^^
  File "C:\_PyPr\New_MCF\.env\Lib\site-packages\bs4\element.py", line 2289, in __getattr__
    raise AttributeError(
AttributeError: ResultSet object has no attribute 'get'. You're probably treating a list of elements like a single element. Did you call find_all() when you meant to call find()?
2023-06-20 12:04:36,522 ERROR list index out of range
Traceback (most recent call last):
  File "C:\_PyPr\New_MCF\mcf_riot_api.py", line 44, in wrapper
    result = func(*args, **kwargs)
             ^^^^^^^^^^^^^^^^^^^^^
  File "C:\_PyPr\New_MCF\mcf_riot_api.py", line 157, in get_poro_games
    if not champ.get('class')[0].startswith('champion'):
           ~~~~~~~~~~~~~~~~~~^^^
IndexError: list index out of range
2023-06-20 12:04:48,229 ERROR list index out of range
Traceback (most recent call last):
  File "C:\_PyPr\New_MCF\mcf_riot_api.py", line 44, in wrapper
    result = func(*args, **kwargs)
             ^^^^^^^^^^^^^^^^^^^^^
  File "C:\_PyPr\New_MCF\mcf_riot_api.py", line 157, in get_poro_games
    if not champ.get('class')[0].startswith('champion'):
           ~~~~~~~~~~~~~~~~~~^^^
IndexError: list index out of range
2023-06-20 12:05:36,275 ERROR 'list' object has no attribute 'startswith'
Traceback (most recent call last):
  File "C:\_PyPr\New_MCF\mcf_riot_api.py", line 44, in wrapper
    result = func(*args, **kwargs)
             ^^^^^^^^^^^^^^^^^^^^^
  File "C:\_PyPr\New_MCF\mcf_riot_api.py", line 157, in get_poro_games
    if not champ.get('class').startswith('champion'):
           ^^^^^^^^^^^^^^^^^^^^^^^^^^^^^
AttributeError: 'list' object has no attribute 'startswith'
2023-06-20 12:05:46,286 ERROR list index out of range
Traceback (most recent call last):
  File "C:\_PyPr\New_MCF\mcf_riot_api.py", line 44, in wrapper
    result = func(*args, **kwargs)
             ^^^^^^^^^^^^^^^^^^^^^
  File "C:\_PyPr\New_MCF\mcf_riot_api.py", line 157, in get_poro_games
    if not champ.get('class')[0].startswith('champion'):
           ~~~~~~~~~~~~~~~~~~^^^
IndexError: list index out of range
2023-06-20 12:08:51,949 ERROR Short
Traceback (most recent call last):
  File "C:\_PyPr\New_MCF\mcf_riot_api.py", line 44, in wrapper
    result = func(*args, **kwargs)
             ^^^^^^^^^^^^^^^^^^^^^
  File "C:\_PyPr\New_MCF\mcf_riot_api.py", line 112, in get_poro_games
    raise MCFException('Short')
mcf_build.MCFException: Short
2023-11-06 10:25:56,714 ERROR Task exception was never retrieved
future: <Task finished name='Task-7' coro=<parse_games.<locals>.parsing() done, defined at C:\python_field\modules\scripts\async_featured_games.py:23> exception=KeyError('gameList')>
Traceback (most recent call last):
  File "C:\python_field\modules\scripts\async_featured_games.py", line 31, in parsing
    gameList = data['gameList']
               ~~~~^^^^^^^^^^^^
KeyError: 'gameList'
2023-11-06 10:25:56,716 ERROR Task exception was never retrieved
future: <Task finished name='Task-8' coro=<parse_games.<locals>.parsing() done, defined at C:\python_field\modules\scripts\async_featured_games.py:23> exception=KeyError('gameList')>
Traceback (most recent call last):
  File "C:\python_field\modules\scripts\async_featured_games.py", line 31, in parsing
    gameList = data['gameList']
               ~~~~^^^^^^^^^^^^
KeyError: 'gameList'
2023-11-06 10:25:56,718 ERROR Task exception was never retrieved
future: <Task finished name='Task-9' coro=<parse_games.<locals>.parsing() done, defined at C:\python_field\modules\scripts\async_featured_games.py:23> exception=KeyError('gameList')>
Traceback (most recent call last):
  File "C:\python_field\modules\scripts\async_featured_games.py", line 31, in parsing
    gameList = data['gameList']
               ~~~~^^^^^^^^^^^^
KeyError: 'gameList'
2023-11-06 10:25:56,719 ERROR Task exception was never retrieved
future: <Task finished name='Task-10' coro=<parse_games.<locals>.parsing() done, defined at C:\python_field\modules\scripts\async_featured_games.py:23> exception=KeyError('gameList')>
Traceback (most recent call last):
  File "C:\python_field\modules\scripts\async_featured_games.py", line 31, in parsing
    gameList = data['gameList']
               ~~~~^^^^^^^^^^^^
KeyError: 'gameList'
2023-11-16 22:44:38,500 ERROR list index out of range
Traceback (most recent call last):
  File "C:\python_field\MCF\mcf_riot_api.py", line 79, in wrapper
    result = func(*args, **kwargs)
             ^^^^^^^^^^^^^^^^^^^^^
  File "C:\python_field\MCF\mcf_riot_api.py", line 197, in get_poro_games
    ids = [int(str(ids.get('class')).split('-')[1]) for ids in game[0:5]]
          ^^^^^^^^^^^^^^^^^^^^^^^^^^^^^^^^^^^^^^^^^^^^^^^^^^^^^^^^^^^^^^^
  File "C:\python_field\MCF\mcf_riot_api.py", line 197, in <listcomp>
    ids = [int(str(ids.get('class')).split('-')[1]) for ids in game[0:5]]
               ~~~~~~~~~~~~~~~~~~~~~~~~~~~~~~~~^^^
IndexError: list index out of range
2023-11-16 22:44:42,363 ERROR list index out of range
Traceback (most recent call last):
  File "C:\python_field\MCF\mcf_riot_api.py", line 79, in wrapper
    result = func(*args, **kwargs)
             ^^^^^^^^^^^^^^^^^^^^^
  File "C:\python_field\MCF\mcf_riot_api.py", line 197, in get_poro_games
    ids = [int(str(ids.get('class')).split('-')[1]) for ids in game[0:5]]
          ^^^^^^^^^^^^^^^^^^^^^^^^^^^^^^^^^^^^^^^^^^^^^^^^^^^^^^^^^^^^^^^
  File "C:\python_field\MCF\mcf_riot_api.py", line 197, in <listcomp>
    ids = [int(str(ids.get('class')).split('-')[1]) for ids in game[0:5]]
               ~~~~~~~~~~~~~~~~~~~~~~~~~~~~~~~~^^^
IndexError: list index out of range
2023-11-16 22:44:55,852 ERROR list index out of range
Traceback (most recent call last):
  File "C:\python_field\MCF\mcf_riot_api.py", line 79, in wrapper
    result = func(*args, **kwargs)
             ^^^^^^^^^^^^^^^^^^^^^
  File "C:\python_field\MCF\mcf_riot_api.py", line 197, in get_poro_games
    ids = [int(str(ids.get('class')).split('-')[1]) for ids in game[0:5]]
          ^^^^^^^^^^^^^^^^^^^^^^^^^^^^^^^^^^^^^^^^^^^^^^^^^^^^^^^^^^^^^^^
  File "C:\python_field\MCF\mcf_riot_api.py", line 197, in <listcomp>
    ids = [int(str(ids.get('class')).split('-')[1]) for ids in game[0:5]]
               ~~~~~~~~~~~~~~~~~~~~~~~~~~~~~~~~^^^
IndexError: list index out of range
2023-11-16 22:46:38,814 ERROR list index out of range
Traceback (most recent call last):
  File "C:\python_field\MCF\mcf_riot_api.py", line 79, in wrapper
    result = func(*args, **kwargs)
             ^^^^^^^^^^^^^^^^^^^^^
  File "C:\python_field\MCF\mcf_riot_api.py", line 197, in get_poro_games
    ids = [int(str(ids.get('class')).split('-')[1]) for ids in game[0:5]]
          ^^^^^^^^^^^^^^^^^^^^^^^^^^^^^^^^^^^^^^^^^^^^^^^^^^^^^^^^^^^^^^^
  File "C:\python_field\MCF\mcf_riot_api.py", line 197, in <listcomp>
    ids = [int(str(ids.get('class')).split('-')[1]) for ids in game[0:5]]
               ~~~~~~~~~~~~~~~~~~~~~~~~~~~~~~~~^^^
IndexError: list index out of range
2023-11-16 22:46:55,332 ERROR list index out of range
Traceback (most recent call last):
  File "C:\python_field\MCF\mcf_riot_api.py", line 79, in wrapper
    result = func(*args, **kwargs)
             ^^^^^^^^^^^^^^^^^^^^^
  File "C:\python_field\MCF\mcf_riot_api.py", line 197, in get_poro_games
    ids = [int(str(ids.get('class')).split('-')[1]) for ids in game[0:5]]
          ^^^^^^^^^^^^^^^^^^^^^^^^^^^^^^^^^^^^^^^^^^^^^^^^^^^^^^^^^^^^^^^
  File "C:\python_field\MCF\mcf_riot_api.py", line 197, in <listcomp>
    ids = [int(str(ids.get('class')).split('-')[1]) for ids in game[0:5]]
               ~~~~~~~~~~~~~~~~~~~~~~~~~~~~~~~~^^^
IndexError: list index out of range
2023-11-17 20:33:05,123 ERROR HTTPSConnectionPool(host='sea.api.riotgames.com', port=443): Read timed out. (read timeout=3)
Traceback (most recent call last):
  File "C:\python_field\MCF\.mcfenv\Lib\site-packages\urllib3\connectionpool.py", line 386, in _make_request
    self._validate_conn(conn)
  File "C:\python_field\MCF\.mcfenv\Lib\site-packages\urllib3\connectionpool.py", line 1042, in _validate_conn
    conn.connect()
  File "C:\python_field\MCF\.mcfenv\Lib\site-packages\urllib3\connection.py", line 414, in connect
    self.sock = ssl_wrap_socket(
                ^^^^^^^^^^^^^^^^
  File "C:\python_field\MCF\.mcfenv\Lib\site-packages\urllib3\util\ssl_.py", line 449, in ssl_wrap_socket
    ssl_sock = _ssl_wrap_socket_impl(
               ^^^^^^^^^^^^^^^^^^^^^^
  File "C:\python_field\MCF\.mcfenv\Lib\site-packages\urllib3\util\ssl_.py", line 493, in _ssl_wrap_socket_impl
    return ssl_context.wrap_socket(sock, server_hostname=server_hostname)
           ^^^^^^^^^^^^^^^^^^^^^^^^^^^^^^^^^^^^^^^^^^^^^^^^^^^^^^^^^^^^^^
  File "C:\Users\New\AppData\Local\Programs\Python\Python311\Lib\ssl.py", line 517, in wrap_socket
    return self.sslsocket_class._create(
           ^^^^^^^^^^^^^^^^^^^^^^^^^^^^^
  File "C:\Users\New\AppData\Local\Programs\Python\Python311\Lib\ssl.py", line 1075, in _create
    self.do_handshake()
  File "C:\Users\New\AppData\Local\Programs\Python\Python311\Lib\ssl.py", line 1346, in do_handshake
    self._sslobj.do_handshake()
TimeoutError: _ssl.c:975: The handshake operation timed out

During handling of the above exception, another exception occurred:

Traceback (most recent call last):
  File "C:\python_field\MCF\.mcfenv\Lib\site-packages\requests\adapters.py", line 489, in send
    resp = conn.urlopen(
           ^^^^^^^^^^^^^
  File "C:\python_field\MCF\.mcfenv\Lib\site-packages\urllib3\connectionpool.py", line 787, in urlopen
    retries = retries.increment(
              ^^^^^^^^^^^^^^^^^^
  File "C:\python_field\MCF\.mcfenv\Lib\site-packages\urllib3\util\retry.py", line 550, in increment
    raise six.reraise(type(error), error, _stacktrace)
          ^^^^^^^^^^^^^^^^^^^^^^^^^^^^^^^^^^^^^^^^^^^^
  File "C:\python_field\MCF\.mcfenv\Lib\site-packages\urllib3\packages\six.py", line 770, in reraise
    raise value
  File "C:\python_field\MCF\.mcfenv\Lib\site-packages\urllib3\connectionpool.py", line 703, in urlopen
    httplib_response = self._make_request(
                       ^^^^^^^^^^^^^^^^^^^
  File "C:\python_field\MCF\.mcfenv\Lib\site-packages\urllib3\connectionpool.py", line 389, in _make_request
    self._raise_timeout(err=e, url=url, timeout_value=conn.timeout)
  File "C:\python_field\MCF\.mcfenv\Lib\site-packages\urllib3\connectionpool.py", line 340, in _raise_timeout
    raise ReadTimeoutError(
urllib3.exceptions.ReadTimeoutError: HTTPSConnectionPool(host='sea.api.riotgames.com', port=443): Read timed out. (read timeout=3)

During handling of the above exception, another exception occurred:

Traceback (most recent call last):
  File "C:\python_field\MCF\mcf_riot_api.py", line 79, in wrapper
    result = func(*args, **kwargs)
             ^^^^^^^^^^^^^^^^^^^^^
  File "C:\python_field\MCF\mcf_riot_api.py", line 113, in get_match_by_gameid
    result = requests.get(RiotAPI.__link_match_by_gameid.format(area=area, gameid=gameid),
            ^^^^^^^^^^^^^^^^^^^^^^^^^^^^^^^^^^^^^^^^^^^^^^^^^^^^^^^^^^^^^^^^^^^^^^^^^^^^^^
  File "C:\python_field\MCF\.mcfenv\Lib\site-packages\requests\api.py", line 73, in get
    return request("get", url, params=params, **kwargs)
           ^^^^^^^^^^^^^^^^^^^^^^^^^^^^^^^^^^^^^^^^^^^^
  File "C:\python_field\MCF\.mcfenv\Lib\site-packages\requests\api.py", line 59, in request
    return session.request(method=method, url=url, **kwargs)
           ^^^^^^^^^^^^^^^^^^^^^^^^^^^^^^^^^^^^^^^^^^^^^^^^^
  File "C:\python_field\MCF\.mcfenv\Lib\site-packages\requests\sessions.py", line 587, in request
    resp = self.send(prep, **send_kwargs)
           ^^^^^^^^^^^^^^^^^^^^^^^^^^^^^^
  File "C:\python_field\MCF\.mcfenv\Lib\site-packages\requests\sessions.py", line 701, in send
    r = adapter.send(request, **kwargs)
        ^^^^^^^^^^^^^^^^^^^^^^^^^^^^^^^
  File "C:\python_field\MCF\.mcfenv\Lib\site-packages\requests\adapters.py", line 578, in send
    raise ReadTimeout(e, request=request)
requests.exceptions.ReadTimeout: HTTPSConnectionPool(host='sea.api.riotgames.com', port=443): Read timed out. (read timeout=3)
2023-11-17 20:33:59,071 ERROR HTTPSConnectionPool(host='sea.api.riotgames.com', port=443): Read timed out. (read timeout=3)
Traceback (most recent call last):
  File "C:\python_field\MCF\.mcfenv\Lib\site-packages\urllib3\connectionpool.py", line 386, in _make_request
    self._validate_conn(conn)
  File "C:\python_field\MCF\.mcfenv\Lib\site-packages\urllib3\connectionpool.py", line 1042, in _validate_conn
    conn.connect()
  File "C:\python_field\MCF\.mcfenv\Lib\site-packages\urllib3\connection.py", line 414, in connect
    self.sock = ssl_wrap_socket(
                ^^^^^^^^^^^^^^^^
  File "C:\python_field\MCF\.mcfenv\Lib\site-packages\urllib3\util\ssl_.py", line 449, in ssl_wrap_socket
    ssl_sock = _ssl_wrap_socket_impl(
               ^^^^^^^^^^^^^^^^^^^^^^
  File "C:\python_field\MCF\.mcfenv\Lib\site-packages\urllib3\util\ssl_.py", line 493, in _ssl_wrap_socket_impl
    return ssl_context.wrap_socket(sock, server_hostname=server_hostname)
           ^^^^^^^^^^^^^^^^^^^^^^^^^^^^^^^^^^^^^^^^^^^^^^^^^^^^^^^^^^^^^^
  File "C:\Users\New\AppData\Local\Programs\Python\Python311\Lib\ssl.py", line 517, in wrap_socket
    return self.sslsocket_class._create(
           ^^^^^^^^^^^^^^^^^^^^^^^^^^^^^
  File "C:\Users\New\AppData\Local\Programs\Python\Python311\Lib\ssl.py", line 1075, in _create
    self.do_handshake()
  File "C:\Users\New\AppData\Local\Programs\Python\Python311\Lib\ssl.py", line 1346, in do_handshake
    self._sslobj.do_handshake()
TimeoutError: _ssl.c:975: The handshake operation timed out

During handling of the above exception, another exception occurred:

Traceback (most recent call last):
  File "C:\python_field\MCF\.mcfenv\Lib\site-packages\requests\adapters.py", line 489, in send
    resp = conn.urlopen(
           ^^^^^^^^^^^^^
  File "C:\python_field\MCF\.mcfenv\Lib\site-packages\urllib3\connectionpool.py", line 787, in urlopen
    retries = retries.increment(
              ^^^^^^^^^^^^^^^^^^
  File "C:\python_field\MCF\.mcfenv\Lib\site-packages\urllib3\util\retry.py", line 550, in increment
    raise six.reraise(type(error), error, _stacktrace)
          ^^^^^^^^^^^^^^^^^^^^^^^^^^^^^^^^^^^^^^^^^^^^
  File "C:\python_field\MCF\.mcfenv\Lib\site-packages\urllib3\packages\six.py", line 770, in reraise
    raise value
  File "C:\python_field\MCF\.mcfenv\Lib\site-packages\urllib3\connectionpool.py", line 703, in urlopen
    httplib_response = self._make_request(
                       ^^^^^^^^^^^^^^^^^^^
  File "C:\python_field\MCF\.mcfenv\Lib\site-packages\urllib3\connectionpool.py", line 389, in _make_request
    self._raise_timeout(err=e, url=url, timeout_value=conn.timeout)
  File "C:\python_field\MCF\.mcfenv\Lib\site-packages\urllib3\connectionpool.py", line 340, in _raise_timeout
    raise ReadTimeoutError(
urllib3.exceptions.ReadTimeoutError: HTTPSConnectionPool(host='sea.api.riotgames.com', port=443): Read timed out. (read timeout=3)

During handling of the above exception, another exception occurred:

Traceback (most recent call last):
  File "C:\python_field\MCF\mcf_riot_api.py", line 79, in wrapper
    result = func(*args, **kwargs)
             ^^^^^^^^^^^^^^^^^^^^^
  File "C:\python_field\MCF\mcf_riot_api.py", line 113, in get_match_by_gameid
    result = requests.get(RiotAPI.__link_match_by_gameid.format(area=area, gameid=gameid),
            ^^^^^^^^^^^^^^^^^^^^^^^^^^^^^^^^^^^^^^^^^^^^^^^^^^^^^^^^^^^^^^^^^^^^^^^^^^^^^^
  File "C:\python_field\MCF\.mcfenv\Lib\site-packages\requests\api.py", line 73, in get
    return request("get", url, params=params, **kwargs)
           ^^^^^^^^^^^^^^^^^^^^^^^^^^^^^^^^^^^^^^^^^^^^
  File "C:\python_field\MCF\.mcfenv\Lib\site-packages\requests\api.py", line 59, in request
    return session.request(method=method, url=url, **kwargs)
           ^^^^^^^^^^^^^^^^^^^^^^^^^^^^^^^^^^^^^^^^^^^^^^^^^
  File "C:\python_field\MCF\.mcfenv\Lib\site-packages\requests\sessions.py", line 587, in request
    resp = self.send(prep, **send_kwargs)
           ^^^^^^^^^^^^^^^^^^^^^^^^^^^^^^
  File "C:\python_field\MCF\.mcfenv\Lib\site-packages\requests\sessions.py", line 701, in send
    r = adapter.send(request, **kwargs)
        ^^^^^^^^^^^^^^^^^^^^^^^^^^^^^^^
  File "C:\python_field\MCF\.mcfenv\Lib\site-packages\requests\adapters.py", line 578, in send
    raise ReadTimeout(e, request=request)
requests.exceptions.ReadTimeout: HTTPSConnectionPool(host='sea.api.riotgames.com', port=443): Read timed out. (read timeout=3)
2023-11-17 20:35:26,309 ERROR HTTPSConnectionPool(host='sea.api.riotgames.com', port=443): Read timed out. (read timeout=3)
Traceback (most recent call last):
  File "C:\python_field\MCF\.mcfenv\Lib\site-packages\urllib3\connectionpool.py", line 386, in _make_request
    self._validate_conn(conn)
  File "C:\python_field\MCF\.mcfenv\Lib\site-packages\urllib3\connectionpool.py", line 1042, in _validate_conn
    conn.connect()
  File "C:\python_field\MCF\.mcfenv\Lib\site-packages\urllib3\connection.py", line 414, in connect
    self.sock = ssl_wrap_socket(
                ^^^^^^^^^^^^^^^^
  File "C:\python_field\MCF\.mcfenv\Lib\site-packages\urllib3\util\ssl_.py", line 449, in ssl_wrap_socket
    ssl_sock = _ssl_wrap_socket_impl(
               ^^^^^^^^^^^^^^^^^^^^^^
  File "C:\python_field\MCF\.mcfenv\Lib\site-packages\urllib3\util\ssl_.py", line 493, in _ssl_wrap_socket_impl
    return ssl_context.wrap_socket(sock, server_hostname=server_hostname)
           ^^^^^^^^^^^^^^^^^^^^^^^^^^^^^^^^^^^^^^^^^^^^^^^^^^^^^^^^^^^^^^
  File "C:\Users\New\AppData\Local\Programs\Python\Python311\Lib\ssl.py", line 517, in wrap_socket
    return self.sslsocket_class._create(
           ^^^^^^^^^^^^^^^^^^^^^^^^^^^^^
  File "C:\Users\New\AppData\Local\Programs\Python\Python311\Lib\ssl.py", line 1075, in _create
    self.do_handshake()
  File "C:\Users\New\AppData\Local\Programs\Python\Python311\Lib\ssl.py", line 1346, in do_handshake
    self._sslobj.do_handshake()
TimeoutError: _ssl.c:975: The handshake operation timed out

During handling of the above exception, another exception occurred:

Traceback (most recent call last):
  File "C:\python_field\MCF\.mcfenv\Lib\site-packages\requests\adapters.py", line 489, in send
    resp = conn.urlopen(
           ^^^^^^^^^^^^^
  File "C:\python_field\MCF\.mcfenv\Lib\site-packages\urllib3\connectionpool.py", line 787, in urlopen
    retries = retries.increment(
              ^^^^^^^^^^^^^^^^^^
  File "C:\python_field\MCF\.mcfenv\Lib\site-packages\urllib3\util\retry.py", line 550, in increment
    raise six.reraise(type(error), error, _stacktrace)
          ^^^^^^^^^^^^^^^^^^^^^^^^^^^^^^^^^^^^^^^^^^^^
  File "C:\python_field\MCF\.mcfenv\Lib\site-packages\urllib3\packages\six.py", line 770, in reraise
    raise value
  File "C:\python_field\MCF\.mcfenv\Lib\site-packages\urllib3\connectionpool.py", line 703, in urlopen
    httplib_response = self._make_request(
                       ^^^^^^^^^^^^^^^^^^^
  File "C:\python_field\MCF\.mcfenv\Lib\site-packages\urllib3\connectionpool.py", line 389, in _make_request
    self._raise_timeout(err=e, url=url, timeout_value=conn.timeout)
  File "C:\python_field\MCF\.mcfenv\Lib\site-packages\urllib3\connectionpool.py", line 340, in _raise_timeout
    raise ReadTimeoutError(
urllib3.exceptions.ReadTimeoutError: HTTPSConnectionPool(host='sea.api.riotgames.com', port=443): Read timed out. (read timeout=3)

During handling of the above exception, another exception occurred:

Traceback (most recent call last):
  File "C:\python_field\MCF\mcf_riot_api.py", line 79, in wrapper
    result = func(*args, **kwargs)
             ^^^^^^^^^^^^^^^^^^^^^
  File "C:\python_field\MCF\mcf_riot_api.py", line 113, in get_match_by_gameid
    result = requests.get(RiotAPI.__link_match_by_gameid.format(area=area, gameid=gameid),
            ^^^^^^^^^^^^^^^^^^^^^^^^^^^^^^^^^^^^^^^^^^^^^^^^^^^^^^^^^^^^^^^^^^^^^^^^^^^^^^
  File "C:\python_field\MCF\.mcfenv\Lib\site-packages\requests\api.py", line 73, in get
    return request("get", url, params=params, **kwargs)
           ^^^^^^^^^^^^^^^^^^^^^^^^^^^^^^^^^^^^^^^^^^^^
  File "C:\python_field\MCF\.mcfenv\Lib\site-packages\requests\api.py", line 59, in request
    return session.request(method=method, url=url, **kwargs)
           ^^^^^^^^^^^^^^^^^^^^^^^^^^^^^^^^^^^^^^^^^^^^^^^^^
  File "C:\python_field\MCF\.mcfenv\Lib\site-packages\requests\sessions.py", line 587, in request
    resp = self.send(prep, **send_kwargs)
           ^^^^^^^^^^^^^^^^^^^^^^^^^^^^^^
  File "C:\python_field\MCF\.mcfenv\Lib\site-packages\requests\sessions.py", line 701, in send
    r = adapter.send(request, **kwargs)
        ^^^^^^^^^^^^^^^^^^^^^^^^^^^^^^^
  File "C:\python_field\MCF\.mcfenv\Lib\site-packages\requests\adapters.py", line 578, in send
    raise ReadTimeout(e, request=request)
requests.exceptions.ReadTimeout: HTTPSConnectionPool(host='sea.api.riotgames.com', port=443): Read timed out. (read timeout=3)
2023-11-17 21:12:03,067 ERROR HTTPSConnectionPool(host='asia.api.riotgames.com', port=443): Read timed out. (read timeout=3)
Traceback (most recent call last):
  File "C:\python_field\MCF\.mcfenv\Lib\site-packages\urllib3\connectionpool.py", line 449, in _make_request
    six.raise_from(e, None)
  File "<string>", line 3, in raise_from
  File "C:\python_field\MCF\.mcfenv\Lib\site-packages\urllib3\connectionpool.py", line 444, in _make_request
    httplib_response = conn.getresponse()
                       ^^^^^^^^^^^^^^^^^^
  File "C:\Users\New\AppData\Local\Programs\Python\Python311\Lib\http\client.py", line 1374, in getresponse
    response.begin()
  File "C:\Users\New\AppData\Local\Programs\Python\Python311\Lib\http\client.py", line 318, in begin
    version, status, reason = self._read_status()
                              ^^^^^^^^^^^^^^^^^^^
  File "C:\Users\New\AppData\Local\Programs\Python\Python311\Lib\http\client.py", line 279, in _read_status
    line = str(self.fp.readline(_MAXLINE + 1), "iso-8859-1")
               ^^^^^^^^^^^^^^^^^^^^^^^^^^^^^^
  File "C:\Users\New\AppData\Local\Programs\Python\Python311\Lib\socket.py", line 705, in readinto
    return self._sock.recv_into(b)
           ^^^^^^^^^^^^^^^^^^^^^^^
  File "C:\Users\New\AppData\Local\Programs\Python\Python311\Lib\ssl.py", line 1278, in recv_into
    return self.read(nbytes, buffer)
           ^^^^^^^^^^^^^^^^^^^^^^^^^
  File "C:\Users\New\AppData\Local\Programs\Python\Python311\Lib\ssl.py", line 1134, in read
    return self._sslobj.read(len, buffer)
           ^^^^^^^^^^^^^^^^^^^^^^^^^^^^^^
TimeoutError: The read operation timed out

During handling of the above exception, another exception occurred:

Traceback (most recent call last):
  File "C:\python_field\MCF\.mcfenv\Lib\site-packages\requests\adapters.py", line 489, in send
    resp = conn.urlopen(
           ^^^^^^^^^^^^^
  File "C:\python_field\MCF\.mcfenv\Lib\site-packages\urllib3\connectionpool.py", line 787, in urlopen
    retries = retries.increment(
              ^^^^^^^^^^^^^^^^^^
  File "C:\python_field\MCF\.mcfenv\Lib\site-packages\urllib3\util\retry.py", line 550, in increment
    raise six.reraise(type(error), error, _stacktrace)
          ^^^^^^^^^^^^^^^^^^^^^^^^^^^^^^^^^^^^^^^^^^^^
  File "C:\python_field\MCF\.mcfenv\Lib\site-packages\urllib3\packages\six.py", line 770, in reraise
    raise value
  File "C:\python_field\MCF\.mcfenv\Lib\site-packages\urllib3\connectionpool.py", line 703, in urlopen
    httplib_response = self._make_request(
                       ^^^^^^^^^^^^^^^^^^^
  File "C:\python_field\MCF\.mcfenv\Lib\site-packages\urllib3\connectionpool.py", line 451, in _make_request
    self._raise_timeout(err=e, url=url, timeout_value=read_timeout)
  File "C:\python_field\MCF\.mcfenv\Lib\site-packages\urllib3\connectionpool.py", line 340, in _raise_timeout
    raise ReadTimeoutError(
urllib3.exceptions.ReadTimeoutError: HTTPSConnectionPool(host='asia.api.riotgames.com', port=443): Read timed out. (read timeout=3)

During handling of the above exception, another exception occurred:

Traceback (most recent call last):
  File "C:\python_field\MCF\mcf_riot_api.py", line 79, in wrapper
    result = func(*args, **kwargs)
             ^^^^^^^^^^^^^^^^^^^^^
  File "C:\python_field\MCF\mcf_riot_api.py", line 113, in get_match_by_gameid
    result = requests.get(RiotAPI.__link_match_by_gameid.format(area=area, gameid=gameid),
            ^^^^^^^^^^^^^^^^^^^^^^^^^^^^^^^^^^^^^^^^^^^^^^^^^^^^^^^^^^^^^^^^^^^^^^^^^^^^^^
  File "C:\python_field\MCF\.mcfenv\Lib\site-packages\requests\api.py", line 73, in get
    return request("get", url, params=params, **kwargs)
           ^^^^^^^^^^^^^^^^^^^^^^^^^^^^^^^^^^^^^^^^^^^^
  File "C:\python_field\MCF\.mcfenv\Lib\site-packages\requests\api.py", line 59, in request
    return session.request(method=method, url=url, **kwargs)
           ^^^^^^^^^^^^^^^^^^^^^^^^^^^^^^^^^^^^^^^^^^^^^^^^^
  File "C:\python_field\MCF\.mcfenv\Lib\site-packages\requests\sessions.py", line 587, in request
    resp = self.send(prep, **send_kwargs)
           ^^^^^^^^^^^^^^^^^^^^^^^^^^^^^^
  File "C:\python_field\MCF\.mcfenv\Lib\site-packages\requests\sessions.py", line 701, in send
    r = adapter.send(request, **kwargs)
        ^^^^^^^^^^^^^^^^^^^^^^^^^^^^^^^
  File "C:\python_field\MCF\.mcfenv\Lib\site-packages\requests\adapters.py", line 578, in send
    raise ReadTimeout(e, request=request)
requests.exceptions.ReadTimeout: HTTPSConnectionPool(host='asia.api.riotgames.com', port=443): Read timed out. (read timeout=3)
2023-11-17 21:14:26,981 ERROR HTTPSConnectionPool(host='asia.api.riotgames.com', port=443): Read timed out. (read timeout=3)
Traceback (most recent call last):
  File "C:\python_field\MCF\.mcfenv\Lib\site-packages\urllib3\connectionpool.py", line 386, in _make_request
    self._validate_conn(conn)
  File "C:\python_field\MCF\.mcfenv\Lib\site-packages\urllib3\connectionpool.py", line 1042, in _validate_conn
    conn.connect()
  File "C:\python_field\MCF\.mcfenv\Lib\site-packages\urllib3\connection.py", line 414, in connect
    self.sock = ssl_wrap_socket(
                ^^^^^^^^^^^^^^^^
  File "C:\python_field\MCF\.mcfenv\Lib\site-packages\urllib3\util\ssl_.py", line 449, in ssl_wrap_socket
    ssl_sock = _ssl_wrap_socket_impl(
               ^^^^^^^^^^^^^^^^^^^^^^
  File "C:\python_field\MCF\.mcfenv\Lib\site-packages\urllib3\util\ssl_.py", line 493, in _ssl_wrap_socket_impl
    return ssl_context.wrap_socket(sock, server_hostname=server_hostname)
           ^^^^^^^^^^^^^^^^^^^^^^^^^^^^^^^^^^^^^^^^^^^^^^^^^^^^^^^^^^^^^^
  File "C:\Users\New\AppData\Local\Programs\Python\Python311\Lib\ssl.py", line 517, in wrap_socket
    return self.sslsocket_class._create(
           ^^^^^^^^^^^^^^^^^^^^^^^^^^^^^
  File "C:\Users\New\AppData\Local\Programs\Python\Python311\Lib\ssl.py", line 1075, in _create
    self.do_handshake()
  File "C:\Users\New\AppData\Local\Programs\Python\Python311\Lib\ssl.py", line 1346, in do_handshake
    self._sslobj.do_handshake()
TimeoutError: _ssl.c:975: The handshake operation timed out

During handling of the above exception, another exception occurred:

Traceback (most recent call last):
  File "C:\python_field\MCF\.mcfenv\Lib\site-packages\requests\adapters.py", line 489, in send
    resp = conn.urlopen(
           ^^^^^^^^^^^^^
  File "C:\python_field\MCF\.mcfenv\Lib\site-packages\urllib3\connectionpool.py", line 787, in urlopen
    retries = retries.increment(
              ^^^^^^^^^^^^^^^^^^
  File "C:\python_field\MCF\.mcfenv\Lib\site-packages\urllib3\util\retry.py", line 550, in increment
    raise six.reraise(type(error), error, _stacktrace)
          ^^^^^^^^^^^^^^^^^^^^^^^^^^^^^^^^^^^^^^^^^^^^
  File "C:\python_field\MCF\.mcfenv\Lib\site-packages\urllib3\packages\six.py", line 770, in reraise
    raise value
  File "C:\python_field\MCF\.mcfenv\Lib\site-packages\urllib3\connectionpool.py", line 703, in urlopen
    httplib_response = self._make_request(
                       ^^^^^^^^^^^^^^^^^^^
  File "C:\python_field\MCF\.mcfenv\Lib\site-packages\urllib3\connectionpool.py", line 389, in _make_request
    self._raise_timeout(err=e, url=url, timeout_value=conn.timeout)
  File "C:\python_field\MCF\.mcfenv\Lib\site-packages\urllib3\connectionpool.py", line 340, in _raise_timeout
    raise ReadTimeoutError(
urllib3.exceptions.ReadTimeoutError: HTTPSConnectionPool(host='asia.api.riotgames.com', port=443): Read timed out. (read timeout=3)

During handling of the above exception, another exception occurred:

Traceback (most recent call last):
  File "C:\python_field\MCF\mcf_riot_api.py", line 79, in wrapper
    result = func(*args, **kwargs)
             ^^^^^^^^^^^^^^^^^^^^^
  File "C:\python_field\MCF\mcf_riot_api.py", line 113, in get_match_by_gameid
    result = requests.get(RiotAPI.__link_match_by_gameid.format(area=area, gameid=gameid),
            ^^^^^^^^^^^^^^^^^^^^^^^^^^^^^^^^^^^^^^^^^^^^^^^^^^^^^^^^^^^^^^^^^^^^^^^^^^^^^^
  File "C:\python_field\MCF\.mcfenv\Lib\site-packages\requests\api.py", line 73, in get
    return request("get", url, params=params, **kwargs)
           ^^^^^^^^^^^^^^^^^^^^^^^^^^^^^^^^^^^^^^^^^^^^
  File "C:\python_field\MCF\.mcfenv\Lib\site-packages\requests\api.py", line 59, in request
    return session.request(method=method, url=url, **kwargs)
           ^^^^^^^^^^^^^^^^^^^^^^^^^^^^^^^^^^^^^^^^^^^^^^^^^
  File "C:\python_field\MCF\.mcfenv\Lib\site-packages\requests\sessions.py", line 587, in request
    resp = self.send(prep, **send_kwargs)
           ^^^^^^^^^^^^^^^^^^^^^^^^^^^^^^
  File "C:\python_field\MCF\.mcfenv\Lib\site-packages\requests\sessions.py", line 701, in send
    r = adapter.send(request, **kwargs)
        ^^^^^^^^^^^^^^^^^^^^^^^^^^^^^^^
  File "C:\python_field\MCF\.mcfenv\Lib\site-packages\requests\adapters.py", line 578, in send
    raise ReadTimeout(e, request=request)
requests.exceptions.ReadTimeout: HTTPSConnectionPool(host='asia.api.riotgames.com', port=443): Read timed out. (read timeout=3)
2023-11-17 21:17:06,620 ERROR HTTPSConnectionPool(host='asia.api.riotgames.com', port=443): Read timed out. (read timeout=3)
Traceback (most recent call last):
  File "C:\python_field\MCF\.mcfenv\Lib\site-packages\urllib3\connectionpool.py", line 386, in _make_request
    self._validate_conn(conn)
  File "C:\python_field\MCF\.mcfenv\Lib\site-packages\urllib3\connectionpool.py", line 1042, in _validate_conn
    conn.connect()
  File "C:\python_field\MCF\.mcfenv\Lib\site-packages\urllib3\connection.py", line 414, in connect
    self.sock = ssl_wrap_socket(
                ^^^^^^^^^^^^^^^^
  File "C:\python_field\MCF\.mcfenv\Lib\site-packages\urllib3\util\ssl_.py", line 449, in ssl_wrap_socket
    ssl_sock = _ssl_wrap_socket_impl(
               ^^^^^^^^^^^^^^^^^^^^^^
  File "C:\python_field\MCF\.mcfenv\Lib\site-packages\urllib3\util\ssl_.py", line 493, in _ssl_wrap_socket_impl
    return ssl_context.wrap_socket(sock, server_hostname=server_hostname)
           ^^^^^^^^^^^^^^^^^^^^^^^^^^^^^^^^^^^^^^^^^^^^^^^^^^^^^^^^^^^^^^
  File "C:\Users\New\AppData\Local\Programs\Python\Python311\Lib\ssl.py", line 517, in wrap_socket
    return self.sslsocket_class._create(
           ^^^^^^^^^^^^^^^^^^^^^^^^^^^^^
  File "C:\Users\New\AppData\Local\Programs\Python\Python311\Lib\ssl.py", line 1075, in _create
    self.do_handshake()
  File "C:\Users\New\AppData\Local\Programs\Python\Python311\Lib\ssl.py", line 1346, in do_handshake
    self._sslobj.do_handshake()
TimeoutError: _ssl.c:975: The handshake operation timed out

During handling of the above exception, another exception occurred:

Traceback (most recent call last):
  File "C:\python_field\MCF\.mcfenv\Lib\site-packages\requests\adapters.py", line 489, in send
    resp = conn.urlopen(
           ^^^^^^^^^^^^^
  File "C:\python_field\MCF\.mcfenv\Lib\site-packages\urllib3\connectionpool.py", line 787, in urlopen
    retries = retries.increment(
              ^^^^^^^^^^^^^^^^^^
  File "C:\python_field\MCF\.mcfenv\Lib\site-packages\urllib3\util\retry.py", line 550, in increment
    raise six.reraise(type(error), error, _stacktrace)
          ^^^^^^^^^^^^^^^^^^^^^^^^^^^^^^^^^^^^^^^^^^^^
  File "C:\python_field\MCF\.mcfenv\Lib\site-packages\urllib3\packages\six.py", line 770, in reraise
    raise value
  File "C:\python_field\MCF\.mcfenv\Lib\site-packages\urllib3\connectionpool.py", line 703, in urlopen
    httplib_response = self._make_request(
                       ^^^^^^^^^^^^^^^^^^^
  File "C:\python_field\MCF\.mcfenv\Lib\site-packages\urllib3\connectionpool.py", line 389, in _make_request
    self._raise_timeout(err=e, url=url, timeout_value=conn.timeout)
  File "C:\python_field\MCF\.mcfenv\Lib\site-packages\urllib3\connectionpool.py", line 340, in _raise_timeout
    raise ReadTimeoutError(
urllib3.exceptions.ReadTimeoutError: HTTPSConnectionPool(host='asia.api.riotgames.com', port=443): Read timed out. (read timeout=3)

During handling of the above exception, another exception occurred:

Traceback (most recent call last):
  File "C:\python_field\MCF\mcf_riot_api.py", line 79, in wrapper
    result = func(*args, **kwargs)
             ^^^^^^^^^^^^^^^^^^^^^
  File "C:\python_field\MCF\mcf_riot_api.py", line 113, in get_match_by_gameid
    result = requests.get(RiotAPI.__link_match_by_gameid.format(area=area, gameid=gameid),
            ^^^^^^^^^^^^^^^^^^^^^^^^^^^^^^^^^^^^^^^^^^^^^^^^^^^^^^^^^^^^^^^^^^^^^^^^^^^^^^
  File "C:\python_field\MCF\.mcfenv\Lib\site-packages\requests\api.py", line 73, in get
    return request("get", url, params=params, **kwargs)
           ^^^^^^^^^^^^^^^^^^^^^^^^^^^^^^^^^^^^^^^^^^^^
  File "C:\python_field\MCF\.mcfenv\Lib\site-packages\requests\api.py", line 59, in request
    return session.request(method=method, url=url, **kwargs)
           ^^^^^^^^^^^^^^^^^^^^^^^^^^^^^^^^^^^^^^^^^^^^^^^^^
  File "C:\python_field\MCF\.mcfenv\Lib\site-packages\requests\sessions.py", line 587, in request
    resp = self.send(prep, **send_kwargs)
           ^^^^^^^^^^^^^^^^^^^^^^^^^^^^^^
  File "C:\python_field\MCF\.mcfenv\Lib\site-packages\requests\sessions.py", line 701, in send
    r = adapter.send(request, **kwargs)
        ^^^^^^^^^^^^^^^^^^^^^^^^^^^^^^^
  File "C:\python_field\MCF\.mcfenv\Lib\site-packages\requests\adapters.py", line 578, in send
    raise ReadTimeout(e, request=request)
requests.exceptions.ReadTimeout: HTTPSConnectionPool(host='asia.api.riotgames.com', port=443): Read timed out. (read timeout=3)
